2017-01-06 07:39:57,668 WARNING 82063 123145314922496 base.py-get_response:152 Not Found: /vcourse/test
2017-01-06 07:40:50,708 WARNING 82084 123145310715904 base.py-get_response:152 Not Found: /vcourse/test
2017-01-06 07:40:51,792 WARNING 82084 123145314922496 base.py-get_response:152 Not Found: /vcourse/test
2017-01-06 07:40:53,076 WARNING 82084 123145319129088 base.py-get_response:152 Not Found: /vcourse/test
2017-01-06 08:18:29,110 WARNING 82532 123145310715904 base.py-get_response:152 Not Found: /user/exist
2017-01-06 08:19:07,736 WARNING 82532 123145310715904 base.py-get_response:152 Not Found: /user/exist
2017-01-06 08:19:13,128 WARNING 82532 123145310715904 csrf.py-_reject:158 Forbidden (CSRF cookie not set.): /user/exists
2017-01-06 08:19:36,873 ERROR 82550 123145310715904 exception.py-handle_uncaught_exception:124 Internal Server Error: /user/exists
Traceback (most recent call last):
  File "/Library/Python/2.7/site-packages/django/core/handlers/exception.py", line 39, in inner
    response = get_response(request)
  File "/Library/Python/2.7/site-packages/django/core/handlers/base.py", line 198, in _get_response
    "returned None instead." % (callback.__module__, view_name)
ValueError: The view vuser.views.userexists didn't return an HttpResponse object. It returned None instead.
2017-01-06 08:20:40,811 ERROR 82557 123145310715904 exception.py-handle_uncaught_exception:124 Internal Server Error: /user/exists
Traceback (most recent call last):
  File "/Library/Python/2.7/site-packages/django/core/handlers/exception.py", line 39, in inner
    response = get_response(request)
  File "/Library/Python/2.7/site-packages/django/core/handlers/base.py", line 187, in _get_response
    response = self.process_exception_by_middleware(e, request)
  File "/Library/Python/2.7/site-packages/django/core/handlers/base.py", line 185, in _get_response
    response = wrapped_callback(request, *callback_args, **callback_kwargs)
  File "/Users/sky-du/workspace/vfastonline/vfast/vuser/views.py", line 21, in userexists
    result = user_is_exists(username=username)
  File "/Users/sky-du/workspace/vfastonline/vfast/vuser/userapi.py", line 12, in user_is_exists
    result = models.User.objects.exists(username=username)
  File "/Library/Python/2.7/site-packages/django/db/models/manager.py", line 85, in manager_method
    return getattr(self.get_queryset(), name)(*args, **kwargs)
TypeError: exists() got an unexpected keyword argument 'username'
2017-01-06 08:23:41,216 WARNING 82602 123145310715904 base.py-get_response:152 Not Found: /user/static/js/test.js
2017-01-06 08:23:41,221 WARNING 82602 123145314922496 base.py-get_response:152 Not Found: /user/static/css/test.css
2017-01-06 08:25:50,265 WARNING 82602 123145314922496 base.py-get_response:152 Not Found: /user/static/js/test.js
2017-01-06 08:25:50,277 WARNING 82602 123145319129088 base.py-get_response:152 Not Found: /user/static/css/test.css
2017-01-06 08:26:01,361 WARNING 82602 123145314922496 base.py-get_response:152 Not Found: /user/static/js/test.js
2017-01-06 08:26:01,376 WARNING 82602 123145319129088 base.py-get_response:152 Not Found: /user/static/css/test.css
2017-01-06 08:26:06,717 ERROR 82622 123145314922496 exception.py-handle_uncaught_exception:124 Internal Server Error: /user/exist
Traceback (most recent call last):
  File "/Library/Python/2.7/site-packages/django/core/handlers/exception.py", line 39, in inner
    response = get_response(request)
  File "/Library/Python/2.7/site-packages/django/core/handlers/base.py", line 187, in _get_response
    response = self.process_exception_by_middleware(e, request)
  File "/Library/Python/2.7/site-packages/django/core/handlers/base.py", line 185, in _get_response
    response = wrapped_callback(request, *callback_args, **callback_kwargs)
  File "/Users/sky-du/workspace/vfastonline/vfast/vuser/views.py", line 21, in userexists
    result = user_is_exists(username=username)
  File "/Users/sky-du/workspace/vfastonline/vfast/vuser/userapi.py", line 12, in user_is_exists
    result = models.User.objects.exists(username=username)
  File "/Library/Python/2.7/site-packages/django/db/models/manager.py", line 85, in manager_method
    return getattr(self.get_queryset(), name)(*args, **kwargs)
TypeError: exists() got an unexpected keyword argument 'username'
2017-01-06 08:27:53,495 ERROR 82648 123145319129088 exception.py-handle_uncaught_exception:124 Internal Server Error: /user/exist
Traceback (most recent call last):
  File "/Library/Python/2.7/site-packages/django/core/handlers/exception.py", line 39, in inner
    response = get_response(request)
  File "/Library/Python/2.7/site-packages/django/core/handlers/base.py", line 187, in _get_response
    response = self.process_exception_by_middleware(e, request)
  File "/Library/Python/2.7/site-packages/django/core/handlers/base.py", line 185, in _get_response
    response = wrapped_callback(request, *callback_args, **callback_kwargs)
  File "/Users/sky-du/workspace/vfastonline/vfast/vuser/views.py", line 21, in userexists
    result = models.User.objects.exists(username=username)
  File "/Library/Python/2.7/site-packages/django/db/models/manager.py", line 85, in manager_method
    return getattr(self.get_queryset(), name)(*args, **kwargs)
TypeError: exists() got an unexpected keyword argument 'username'
2017-01-06 08:28:48,460 ERROR 82660 123145310715904 exception.py-handle_uncaught_exception:124 Internal Server Error: /user/exist
Traceback (most recent call last):
  File "/Library/Python/2.7/site-packages/django/core/handlers/exception.py", line 39, in inner
    response = get_response(request)
  File "/Library/Python/2.7/site-packages/django/core/handlers/base.py", line 187, in _get_response
    response = self.process_exception_by_middleware(e, request)
  File "/Library/Python/2.7/site-packages/django/core/handlers/base.py", line 185, in _get_response
    response = wrapped_callback(request, *callback_args, **callback_kwargs)
  File "/Users/sky-du/workspace/vfastonline/vfast/vuser/views.py", line 21, in userexists
    result = models.User.objects.exists(username=username)
  File "/Library/Python/2.7/site-packages/django/db/models/manager.py", line 85, in manager_method
    return getattr(self.get_queryset(), name)(*args, **kwargs)
TypeError: exists() got an unexpected keyword argument 'username'
2017-01-06 08:34:36,791 ERROR 82711 123145310715904 exception.py-handle_uncaught_exception:124 Internal Server Error: /user/exist
Traceback (most recent call last):
  File "/Library/Python/2.7/site-packages/django/core/handlers/exception.py", line 39, in inner
    response = get_response(request)
  File "/Library/Python/2.7/site-packages/django/core/handlers/base.py", line 198, in _get_response
    "returned None instead." % (callback.__module__, view_name)
ValueError: The view vuser.views.userexists didn't return an HttpResponse object. It returned None instead.
2017-01-06 09:31:21,673 ERROR 83378 123145310715904 views.py-register:78 Traceback (most recent call last):
  File "/Users/sky-du/workspace/vfastonline/vfast/vuser/views.py", line 72, in register
    learn_habit=learn_habit, active=active)
  File "/Library/Python/2.7/site-packages/django/db/models/manager.py", line 85, in manager_method
    return getattr(self.get_queryset(), name)(*args, **kwargs)
  File "/Library/Python/2.7/site-packages/django/db/models/query.py", line 471, in get_or_create
    return self.get(**lookup), False
  File "/Library/Python/2.7/site-packages/django/db/models/query.py", line 376, in get
    clone = self.filter(*args, **kwargs)
  File "/Library/Python/2.7/site-packages/django/db/models/query.py", line 794, in filter
    return self._filter_or_exclude(False, *args, **kwargs)
  File "/Library/Python/2.7/site-packages/django/db/models/query.py", line 812, in _filter_or_exclude
    clone.query.add_q(Q(*args, **kwargs))
  File "/Library/Python/2.7/site-packages/django/db/models/sql/query.py", line 1227, in add_q
    clause, _ = self._add_q(q_object, self.used_aliases)
  File "/Library/Python/2.7/site-packages/django/db/models/sql/query.py", line 1253, in _add_q
    allow_joins=allow_joins, split_subq=split_subq,
  File "/Library/Python/2.7/site-packages/django/db/models/sql/query.py", line 1133, in build_filter
    lookups, parts, reffed_expression = self.solve_lookup_type(arg)
  File "/Library/Python/2.7/site-packages/django/db/models/sql/query.py", line 1019, in solve_lookup_type
    _, field, _, lookup_parts = self.names_to_path(lookup_splitted, self.get_meta())
  File "/Library/Python/2.7/site-packages/django/db/models/sql/query.py", line 1327, in names_to_path
    "Choices are: %s" % (name, ", ".join(available)))
FieldError: Cannot resolve keyword 'learn_habit' into field. Choices are: active, birthday, comp_use_time_day, company_location, createtime, current_company, email, expect_job, expect_level, githuburl, id, into_it, intro, is_open, linkinurl, location, mugshot, mugshotframe, password, personpage, program_exp, realname, score, sex, stackoverflowurl, status, totalscore, userbadge, username, video, watchrecord

2017-01-06 09:32:12,475 ERROR 83378 123145310715904 views.py-register:78 Traceback (most recent call last):
  File "/Users/sky-du/workspace/vfastonline/vfast/vuser/views.py", line 72, in register
    learn_habit=learn_habit, active=active)
  File "/Library/Python/2.7/site-packages/django/db/models/manager.py", line 85, in manager_method
    return getattr(self.get_queryset(), name)(*args, **kwargs)
  File "/Library/Python/2.7/site-packages/django/db/models/query.py", line 471, in get_or_create
    return self.get(**lookup), False
  File "/Library/Python/2.7/site-packages/django/db/models/query.py", line 376, in get
    clone = self.filter(*args, **kwargs)
  File "/Library/Python/2.7/site-packages/django/db/models/query.py", line 794, in filter
    return self._filter_or_exclude(False, *args, **kwargs)
  File "/Library/Python/2.7/site-packages/django/db/models/query.py", line 812, in _filter_or_exclude
    clone.query.add_q(Q(*args, **kwargs))
  File "/Library/Python/2.7/site-packages/django/db/models/sql/query.py", line 1227, in add_q
    clause, _ = self._add_q(q_object, self.used_aliases)
  File "/Library/Python/2.7/site-packages/django/db/models/sql/query.py", line 1253, in _add_q
    allow_joins=allow_joins, split_subq=split_subq,
  File "/Library/Python/2.7/site-packages/django/db/models/sql/query.py", line 1133, in build_filter
    lookups, parts, reffed_expression = self.solve_lookup_type(arg)
  File "/Library/Python/2.7/site-packages/django/db/models/sql/query.py", line 1019, in solve_lookup_type
    _, field, _, lookup_parts = self.names_to_path(lookup_splitted, self.get_meta())
  File "/Library/Python/2.7/site-packages/django/db/models/sql/query.py", line 1327, in names_to_path
    "Choices are: %s" % (name, ", ".join(available)))
FieldError: Cannot resolve keyword 'learn_habit' into field. Choices are: active, birthday, comp_use_time_day, company_location, createtime, current_company, email, expect_job, expect_level, githuburl, id, into_it, intro, is_open, linkinurl, location, mugshot, mugshotframe, password, personpage, program_exp, realname, score, sex, stackoverflowurl, status, totalscore, userbadge, username, video, watchrecord

2017-01-06 09:34:43,724 ERROR 83427 123145310715904 views.py-register:78 Traceback (most recent call last):
  File "/Users/sky-du/workspace/vfastonline/vfast/vuser/views.py", line 72, in register
    learn_habit=learn_habit, active=active)
  File "/Library/Python/2.7/site-packages/django/db/models/manager.py", line 85, in manager_method
    return getattr(self.get_queryset(), name)(*args, **kwargs)
  File "/Library/Python/2.7/site-packages/django/db/models/query.py", line 473, in get_or_create
    return self._create_object_from_params(lookup, params)
  File "/Library/Python/2.7/site-packages/django/db/models/query.py", line 511, in _create_object_from_params
    six.reraise(*exc_info)
  File "/Library/Python/2.7/site-packages/django/db/models/query.py", line 503, in _create_object_from_params
    obj = self.create(**params)
  File "/Library/Python/2.7/site-packages/django/db/models/query.py", line 399, in create
    obj.save(force_insert=True, using=self.db)
  File "/Library/Python/2.7/site-packages/django/db/models/base.py", line 796, in save
    force_update=force_update, update_fields=update_fields)
  File "/Library/Python/2.7/site-packages/django/db/models/base.py", line 824, in save_base
    updated = self._save_table(raw, cls, force_insert, force_update, using, update_fields)
  File "/Library/Python/2.7/site-packages/django/db/models/base.py", line 908, in _save_table
    result = self._do_insert(cls._base_manager, using, fields, update_pk, raw)
  File "/Library/Python/2.7/site-packages/django/db/models/base.py", line 947, in _do_insert
    using=using, raw=raw)
  File "/Library/Python/2.7/site-packages/django/db/models/manager.py", line 85, in manager_method
    return getattr(self.get_queryset(), name)(*args, **kwargs)
  File "/Library/Python/2.7/site-packages/django/db/models/query.py", line 1043, in _insert
    return query.get_compiler(using=using).execute_sql(return_id)
  File "/Library/Python/2.7/site-packages/django/db/models/sql/compiler.py", line 1054, in execute_sql
    cursor.execute(sql, params)
  File "/Library/Python/2.7/site-packages/django/db/backends/utils.py", line 79, in execute
    return super(CursorDebugWrapper, self).execute(sql, params)
  File "/Library/Python/2.7/site-packages/django/db/backends/utils.py", line 64, in execute
    return self.cursor.execute(sql, params)
  File "/Library/Python/2.7/site-packages/django/db/utils.py", line 94, in __exit__
    six.reraise(dj_exc_type, dj_exc_value, traceback)
  File "/Library/Python/2.7/site-packages/django/db/backends/utils.py", line 64, in execute
    return self.cursor.execute(sql, params)
  File "/Library/Python/2.7/site-packages/django/db/backends/sqlite3/base.py", line 337, in execute
    return Database.Cursor.execute(self, query, params)
IntegrityError: NOT NULL constraint failed: vuser_user.sex

2017-01-06 09:51:40,610 ERROR 83571 123145310715904 views.py-register:79 Traceback (most recent call last):
  File "/Users/sky-du/workspace/vfastonline/vfast/vuser/views.py", line 58, in register
    active = base64.b64decode('%s|%s|%s' % (email, settings.SECRET_KEY, int(time.time())))
  File "/System/Library/Frameworks/Python.framework/Versions/2.7/lib/python2.7/base64.py", line 76, in b64decode
    raise TypeError(msg)
TypeError: Incorrect padding

2017-01-06 09:53:11,608 ERROR 83589 123145310715904 views.py-register:80 Traceback (most recent call last):
  File "/Users/sky-du/workspace/vfastonline/vfast/vuser/views.py", line 59, in register
    active = base64.b64decode('%s|%s|%s' % (email, settings.SECRET_KEY, t))
  File "/System/Library/Frameworks/Python.framework/Versions/2.7/lib/python2.7/base64.py", line 76, in b64decode
    raise TypeError(msg)
TypeError: Incorrect padding

2017-01-06 09:59:16,871 WARNING 83679 123145310715904 base.py-get_response:152 Not Found: /vuser/active
2017-01-07 11:32:44,297 WARNING 981 123145310715904 base.py-get_response:152 Not Found: /favicon.ico
2017-01-07 12:26:23,301 WARNING 1601 123145310715904 base.py-get_response:152 Not Found: /user/detail
2017-01-07 12:26:29,970 ERROR 1601 123145310715904 views.py-userdetail:176 Traceback (most recent call last):
  File "/Users/sky-du/workspace/vfastonline/vfast/vuser/views.py", line 172, in userdetail
    user = models.User.objects.get(id=uid)
  File "/Library/Python/2.7/site-packages/django/db/models/manager.py", line 85, in manager_method
    return getattr(self.get_queryset(), name)(*args, **kwargs)
  File "/Library/Python/2.7/site-packages/django/db/models/query.py", line 376, in get
    clone = self.filter(*args, **kwargs)
  File "/Library/Python/2.7/site-packages/django/db/models/query.py", line 794, in filter
    return self._filter_or_exclude(False, *args, **kwargs)
  File "/Library/Python/2.7/site-packages/django/db/models/query.py", line 812, in _filter_or_exclude
    clone.query.add_q(Q(*args, **kwargs))
  File "/Library/Python/2.7/site-packages/django/db/models/sql/query.py", line 1227, in add_q
    clause, _ = self._add_q(q_object, self.used_aliases)
  File "/Library/Python/2.7/site-packages/django/db/models/sql/query.py", line 1253, in _add_q
    allow_joins=allow_joins, split_subq=split_subq,
  File "/Library/Python/2.7/site-packages/django/db/models/sql/query.py", line 1187, in build_filter
    condition = self.build_lookup(lookups, col, value)
  File "/Library/Python/2.7/site-packages/django/db/models/sql/query.py", line 1083, in build_lookup
    return final_lookup(lhs, rhs)
  File "/Library/Python/2.7/site-packages/django/db/models/lookups.py", line 19, in __init__
    self.rhs = self.get_prep_lookup()
  File "/Library/Python/2.7/site-packages/django/db/models/lookups.py", line 59, in get_prep_lookup
    return self.lhs.output_field.get_prep_value(self.rhs)
  File "/Library/Python/2.7/site-packages/django/db/models/fields/__init__.py", line 946, in get_prep_value
    return int(value)
ValueError: invalid literal for int() with base 10: ''

2017-01-09 02:24:11,876 WARNING 11923 123145310715904 base.py-get_response:152 Not Found: /favicon.ico
2017-01-09 02:24:16,840 WARNING 11923 123145310715904 base.py-get_response:152 Not Found: /badge/add
2017-01-09 02:26:42,872 WARNING 11952 123145310715904 base.py-get_response:152 Not Found: /badge/add
2017-01-09 02:30:14,630 ERROR 11957 123145314922496 views.py-badge_add:28 Traceback (most recent call last):
  File "/Users/sky-du/workspace/vfastonline/vfast/badge/views.py", line 17, in badge_add
    badgeimg = request.FILES['badgeimg']
  File "/Library/Python/2.7/site-packages/django/utils/datastructures.py", line 85, in __getitem__
    raise MultiValueDictKeyError(repr(key))
MultiValueDictKeyError: "'badgeimg'"

2017-01-09 02:31:11,703 ERROR 11957 123145310715904 views.py-badge_add:28 Traceback (most recent call last):
  File "/Users/sky-du/workspace/vfastonline/vfast/badge/views.py", line 24, in badge_add
    print badgename, cid_object.name, filename, uploaded_file_url
AttributeError: 'QuerySet' object has no attribute 'name'

2017-01-09 02:32:04,776 ERROR 11997 123145310715904 views.py-badge_add:28 Traceback (most recent call last):
  File "/Users/sky-du/workspace/vfastonline/vfast/badge/views.py", line 24, in badge_add
    print badgename, cid_object.name, filename, uploaded_file_url
AttributeError: 'QuerySet' object has no attribute 'name'

2017-01-09 02:40:45,206 WARNING 12089 123145310715904 base.py-get_response:152 Not Found: //meizitu_eCUubjt.jpg
2017-01-09 02:40:48,832 WARNING 12089 123145314922496 base.py-get_response:152 Not Found: /meizitu_eCUubjt.jpg
2017-01-09 02:59:22,384 ERROR 12383 123145310715904 views.py-badge_get:43 Traceback (most recent call last):
  File "/Users/sky-du/workspace/vfastonline/vfast/badge/views.py", line 39, in badge_get
    badge = get_object(Badge, key=value)
  File "/Users/sky-du/workspace/vfastonline/vfast/vfast/api.py", line 116, in get_object
    the_object = model.objects.get(**kwargs)
  File "/Library/Python/2.7/site-packages/django/db/models/manager.py", line 85, in manager_method
    return getattr(self.get_queryset(), name)(*args, **kwargs)
  File "/Library/Python/2.7/site-packages/django/db/models/query.py", line 376, in get
    clone = self.filter(*args, **kwargs)
  File "/Library/Python/2.7/site-packages/django/db/models/query.py", line 794, in filter
    return self._filter_or_exclude(False, *args, **kwargs)
  File "/Library/Python/2.7/site-packages/django/db/models/query.py", line 812, in _filter_or_exclude
    clone.query.add_q(Q(*args, **kwargs))
  File "/Library/Python/2.7/site-packages/django/db/models/sql/query.py", line 1227, in add_q
    clause, _ = self._add_q(q_object, self.used_aliases)
  File "/Library/Python/2.7/site-packages/django/db/models/sql/query.py", line 1253, in _add_q
    allow_joins=allow_joins, split_subq=split_subq,
  File "/Library/Python/2.7/site-packages/django/db/models/sql/query.py", line 1133, in build_filter
    lookups, parts, reffed_expression = self.solve_lookup_type(arg)
  File "/Library/Python/2.7/site-packages/django/db/models/sql/query.py", line 1019, in solve_lookup_type
    _, field, _, lookup_parts = self.names_to_path(lookup_splitted, self.get_meta())
  File "/Library/Python/2.7/site-packages/django/db/models/sql/query.py", line 1327, in names_to_path
    "Choices are: %s" % (name, ", ".join(available)))
FieldError: Cannot resolve keyword 'key' into field. Choices are: badgename, badgeurl, cid, cid_id, createtime, id, userbadge

2017-01-09 03:00:25,089 ERROR 12397 123145310715904 views.py-badge_get:44 Traceback (most recent call last):
  File "/Users/sky-du/workspace/vfastonline/vfast/badge/views.py", line 40, in badge_get
    badge = get_object(Badge, key=value)
  File "/Users/sky-du/workspace/vfastonline/vfast/vfast/api.py", line 116, in get_object
    the_object = model.objects.get(**kwargs)
  File "/Library/Python/2.7/site-packages/django/db/models/manager.py", line 85, in manager_method
    return getattr(self.get_queryset(), name)(*args, **kwargs)
  File "/Library/Python/2.7/site-packages/django/db/models/query.py", line 376, in get
    clone = self.filter(*args, **kwargs)
  File "/Library/Python/2.7/site-packages/django/db/models/query.py", line 794, in filter
    return self._filter_or_exclude(False, *args, **kwargs)
  File "/Library/Python/2.7/site-packages/django/db/models/query.py", line 812, in _filter_or_exclude
    clone.query.add_q(Q(*args, **kwargs))
  File "/Library/Python/2.7/site-packages/django/db/models/sql/query.py", line 1227, in add_q
    clause, _ = self._add_q(q_object, self.used_aliases)
  File "/Library/Python/2.7/site-packages/django/db/models/sql/query.py", line 1253, in _add_q
    allow_joins=allow_joins, split_subq=split_subq,
  File "/Library/Python/2.7/site-packages/django/db/models/sql/query.py", line 1133, in build_filter
    lookups, parts, reffed_expression = self.solve_lookup_type(arg)
  File "/Library/Python/2.7/site-packages/django/db/models/sql/query.py", line 1019, in solve_lookup_type
    _, field, _, lookup_parts = self.names_to_path(lookup_splitted, self.get_meta())
  File "/Library/Python/2.7/site-packages/django/db/models/sql/query.py", line 1327, in names_to_path
    "Choices are: %s" % (name, ", ".join(available)))
FieldError: Cannot resolve keyword 'key' into field. Choices are: badgename, badgeurl, cid, cid_id, createtime, id, userbadge

2017-01-09 03:03:24,269 ERROR 12424 123145310715904 views.py-badge_get:44 Traceback (most recent call last):
  File "/Users/sky-du/workspace/vfastonline/vfast/badge/views.py", line 40, in badge_get
    badge = get_object(Badge, key=value)
  File "/Users/sky-du/workspace/vfastonline/vfast/vfast/api.py", line 117, in get_object
    the_object = model.objects.get(**kwargs)
  File "/Library/Python/2.7/site-packages/django/db/models/manager.py", line 85, in manager_method
    return getattr(self.get_queryset(), name)(*args, **kwargs)
  File "/Library/Python/2.7/site-packages/django/db/models/query.py", line 376, in get
    clone = self.filter(*args, **kwargs)
  File "/Library/Python/2.7/site-packages/django/db/models/query.py", line 794, in filter
    return self._filter_or_exclude(False, *args, **kwargs)
  File "/Library/Python/2.7/site-packages/django/db/models/query.py", line 812, in _filter_or_exclude
    clone.query.add_q(Q(*args, **kwargs))
  File "/Library/Python/2.7/site-packages/django/db/models/sql/query.py", line 1227, in add_q
    clause, _ = self._add_q(q_object, self.used_aliases)
  File "/Library/Python/2.7/site-packages/django/db/models/sql/query.py", line 1253, in _add_q
    allow_joins=allow_joins, split_subq=split_subq,
  File "/Library/Python/2.7/site-packages/django/db/models/sql/query.py", line 1133, in build_filter
    lookups, parts, reffed_expression = self.solve_lookup_type(arg)
  File "/Library/Python/2.7/site-packages/django/db/models/sql/query.py", line 1019, in solve_lookup_type
    _, field, _, lookup_parts = self.names_to_path(lookup_splitted, self.get_meta())
  File "/Library/Python/2.7/site-packages/django/db/models/sql/query.py", line 1327, in names_to_path
    "Choices are: %s" % (name, ", ".join(available)))
FieldError: Cannot resolve keyword 'key' into field. Choices are: badgename, badgeurl, cid, cid_id, createtime, id, userbadge

2017-01-09 03:06:53,680 ERROR 12460 123145314922496 views.py-badge_get:45 Traceback (most recent call last):
  File "/Users/sky-du/workspace/vfastonline/vfast/badge/views.py", line 41, in badge_get
    badge = get_object(Badge, id=id())
TypeError: 'NoneType' object is not callable

2017-01-09 03:07:29,201 ERROR 12469 123145310715904 views.py-badge_get:46 Traceback (most recent call last):
  File "/Users/sky-du/workspace/vfastonline/vfast/badge/views.py", line 42, in badge_get
    badge = get_object(Badge, id=id())
TypeError: 'NoneType' object is not callable

2017-01-09 03:07:31,670 ERROR 12469 123145314922496 views.py-badge_get:46 Traceback (most recent call last):
  File "/Users/sky-du/workspace/vfastonline/vfast/badge/views.py", line 42, in badge_get
    badge = get_object(Badge, id=id())
TypeError: 'NoneType' object is not callable

2017-01-09 03:07:51,410 ERROR 12476 123145310715904 views.py-badge_get:47 Traceback (most recent call last):
  File "/Users/sky-du/workspace/vfastonline/vfast/badge/views.py", line 43, in badge_get
    badge = get_object(Badge, id=id())
TypeError: 'NoneType' object is not callable

2017-01-09 03:07:55,565 ERROR 12476 123145314922496 views.py-badge_get:47 Traceback (most recent call last):
  File "/Users/sky-du/workspace/vfastonline/vfast/badge/views.py", line 43, in badge_get
    badge = get_object(Badge, id=id())
TypeError: 'NoneType' object is not callable

2017-01-09 03:08:52,231 ERROR 12491 123145310715904 views.py-badge_get:47 Traceback (most recent call last):
  File "/Users/sky-du/workspace/vfastonline/vfast/badge/views.py", line 43, in badge_get
    badge = get_object(Badge, badgename=badgename)
  File "/Users/sky-du/workspace/vfastonline/vfast/vfast/api.py", line 117, in get_object
    the_object = model.objects.get(**kwargs)
  File "/Library/Python/2.7/site-packages/django/db/models/manager.py", line 85, in manager_method
    return getattr(self.get_queryset(), name)(*args, **kwargs)
  File "/Library/Python/2.7/site-packages/django/db/models/query.py", line 389, in get
    (self.model._meta.object_name, num)
MultipleObjectsReturned: get() returned more than one Badge -- it returned 2!

2017-01-09 03:09:14,374 ERROR 12491 123145310715904 views.py-badge_get:47 Traceback (most recent call last):
  File "/Users/sky-du/workspace/vfastonline/vfast/badge/views.py", line 43, in badge_get
    badge = get_object(Badge, badgename=badgename)
  File "/Users/sky-du/workspace/vfastonline/vfast/vfast/api.py", line 117, in get_object
    the_object = model.objects.get(**kwargs)
  File "/Library/Python/2.7/site-packages/django/db/models/manager.py", line 85, in manager_method
    return getattr(self.get_queryset(), name)(*args, **kwargs)
  File "/Library/Python/2.7/site-packages/django/db/models/query.py", line 389, in get
    (self.model._meta.object_name, num)
MultipleObjectsReturned: get() returned more than one Badge -- it returned 2!

2017-01-09 03:09:47,939 ERROR 12501 123145310715904 views.py-badge_get:48 Traceback (most recent call last):
  File "/Users/sky-du/workspace/vfastonline/vfast/badge/views.py", line 44, in badge_get
    badge = get_object(Badge, badgename=badgename)
  File "/Users/sky-du/workspace/vfastonline/vfast/vfast/api.py", line 117, in get_object
    the_object = model.objects.get(**kwargs)
  File "/Library/Python/2.7/site-packages/django/db/models/manager.py", line 85, in manager_method
    return getattr(self.get_queryset(), name)(*args, **kwargs)
  File "/Library/Python/2.7/site-packages/django/db/models/query.py", line 389, in get
    (self.model._meta.object_name, num)
MultipleObjectsReturned: get() returned more than one Badge -- it returned 2!

2017-01-09 03:09:48,858 ERROR 12501 123145314922496 views.py-badge_get:48 Traceback (most recent call last):
  File "/Users/sky-du/workspace/vfastonline/vfast/badge/views.py", line 44, in badge_get
    badge = get_object(Badge, badgename=badgename)
  File "/Users/sky-du/workspace/vfastonline/vfast/vfast/api.py", line 117, in get_object
    the_object = model.objects.get(**kwargs)
  File "/Library/Python/2.7/site-packages/django/db/models/manager.py", line 85, in manager_method
    return getattr(self.get_queryset(), name)(*args, **kwargs)
  File "/Library/Python/2.7/site-packages/django/db/models/query.py", line 389, in get
    (self.model._meta.object_name, num)
MultipleObjectsReturned: get() returned more than one Badge -- it returned 2!

2017-01-09 03:09:55,091 ERROR 12501 123145310715904 views.py-badge_get:48 Traceback (most recent call last):
  File "/Users/sky-du/workspace/vfastonline/vfast/badge/views.py", line 44, in badge_get
    badge = get_object(Badge, badgename=badgename)
  File "/Users/sky-du/workspace/vfastonline/vfast/vfast/api.py", line 117, in get_object
    the_object = model.objects.get(**kwargs)
  File "/Library/Python/2.7/site-packages/django/db/models/manager.py", line 85, in manager_method
    return getattr(self.get_queryset(), name)(*args, **kwargs)
  File "/Library/Python/2.7/site-packages/django/db/models/query.py", line 389, in get
    (self.model._meta.object_name, num)
MultipleObjectsReturned: get() returned more than one Badge -- it returned 2!

2017-01-09 03:10:19,851 ERROR 12510 123145310715904 views.py-badge_get:48 Traceback (most recent call last):
  File "/Users/sky-du/workspace/vfastonline/vfast/badge/views.py", line 44, in badge_get
    badge = get_object(Badge, badgename=badgename)
  File "/Users/sky-du/workspace/vfastonline/vfast/vfast/api.py", line 117, in get_object
    the_object = model.objects.get(**kwargs)
  File "/Library/Python/2.7/site-packages/django/db/models/manager.py", line 85, in manager_method
    return getattr(self.get_queryset(), name)(*args, **kwargs)
  File "/Library/Python/2.7/site-packages/django/db/models/query.py", line 389, in get
    (self.model._meta.object_name, num)
MultipleObjectsReturned: get() returned more than one Badge -- it returned 2!

2017-01-09 03:11:16,330 ERROR 12510 123145310715904 views.py-badge_get:48 Traceback (most recent call last):
  File "/Users/sky-du/workspace/vfastonline/vfast/badge/views.py", line 45, in badge_get
    print badge.cratetime
AttributeError: 'Badge' object has no attribute 'cratetime'

2017-01-09 03:12:05,145 ERROR 12510 123145310715904 views.py-badge_get:48 Traceback (most recent call last):
  File "/Users/sky-du/workspace/vfastonline/vfast/badge/views.py", line 45, in badge_get
    print badge.cratetime
AttributeError: 'Badge' object has no attribute 'cratetime'

2017-01-09 03:12:16,420 ERROR 12533 123145310715904 views.py-badge_get:48 Traceback (most recent call last):
  File "/Users/sky-du/workspace/vfastonline/vfast/badge/views.py", line 45, in badge_get
    print badge.cratetime
AttributeError: 'Badge' object has no attribute 'cratetime'

2017-01-09 03:14:23,790 ERROR 12554 123145310715904 views.py-badge_get:48 Traceback (most recent call last):
  File "/Users/sky-du/workspace/vfastonline/vfast/badge/views.py", line 45, in badge_get
    print badge.cratetime
AttributeError: 'Badge' object has no attribute 'cratetime'

2017-01-09 03:14:29,316 ERROR 12554 123145314922496 views.py-badge_get:48 Traceback (most recent call last):
  File "/Users/sky-du/workspace/vfastonline/vfast/badge/views.py", line 45, in badge_get
    print badge.cratetime
AttributeError: 'Badge' object has no attribute 'cratetime'

2017-01-09 03:15:13,685 ERROR 12571 123145310715904 views.py-badge_get:48 Traceback (most recent call last):
  File "/Users/sky-du/workspace/vfastonline/vfast/badge/views.py", line 39, in badge_get
    badge = Badge.objects.get(Badge, id=id)
  File "/Library/Python/2.7/site-packages/django/db/models/manager.py", line 85, in manager_method
    return getattr(self.get_queryset(), name)(*args, **kwargs)
  File "/Library/Python/2.7/site-packages/django/db/models/query.py", line 376, in get
    clone = self.filter(*args, **kwargs)
  File "/Library/Python/2.7/site-packages/django/db/models/query.py", line 794, in filter
    return self._filter_or_exclude(False, *args, **kwargs)
  File "/Library/Python/2.7/site-packages/django/db/models/query.py", line 812, in _filter_or_exclude
    clone.query.add_q(Q(*args, **kwargs))
  File "/Library/Python/2.7/site-packages/django/db/models/sql/query.py", line 1227, in add_q
    clause, _ = self._add_q(q_object, self.used_aliases)
  File "/Library/Python/2.7/site-packages/django/db/models/sql/query.py", line 1253, in _add_q
    allow_joins=allow_joins, split_subq=split_subq,
  File "/Library/Python/2.7/site-packages/django/db/models/sql/query.py", line 1130, in build_filter
    arg, value = filter_expr
TypeError: 'ModelBase' object is not iterable

2017-01-09 03:15:29,480 ERROR 12571 123145310715904 views.py-badge_get:48 Traceback (most recent call last):
  File "/Users/sky-du/workspace/vfastonline/vfast/badge/views.py", line 39, in badge_get
    badge = Badge.objects.get(Badge, id=id)
  File "/Library/Python/2.7/site-packages/django/db/models/manager.py", line 85, in manager_method
    return getattr(self.get_queryset(), name)(*args, **kwargs)
  File "/Library/Python/2.7/site-packages/django/db/models/query.py", line 376, in get
    clone = self.filter(*args, **kwargs)
  File "/Library/Python/2.7/site-packages/django/db/models/query.py", line 794, in filter
    return self._filter_or_exclude(False, *args, **kwargs)
  File "/Library/Python/2.7/site-packages/django/db/models/query.py", line 812, in _filter_or_exclude
    clone.query.add_q(Q(*args, **kwargs))
  File "/Library/Python/2.7/site-packages/django/db/models/sql/query.py", line 1227, in add_q
    clause, _ = self._add_q(q_object, self.used_aliases)
  File "/Library/Python/2.7/site-packages/django/db/models/sql/query.py", line 1253, in _add_q
    allow_joins=allow_joins, split_subq=split_subq,
  File "/Library/Python/2.7/site-packages/django/db/models/sql/query.py", line 1130, in build_filter
    arg, value = filter_expr
TypeError: 'ModelBase' object is not iterable

2017-01-09 03:15:32,884 ERROR 12571 123145314922496 views.py-badge_get:48 Traceback (most recent call last):
  File "/Users/sky-du/workspace/vfastonline/vfast/badge/views.py", line 39, in badge_get
    badge = Badge.objects.get(Badge, id=id)
  File "/Library/Python/2.7/site-packages/django/db/models/manager.py", line 85, in manager_method
    return getattr(self.get_queryset(), name)(*args, **kwargs)
  File "/Library/Python/2.7/site-packages/django/db/models/query.py", line 376, in get
    clone = self.filter(*args, **kwargs)
  File "/Library/Python/2.7/site-packages/django/db/models/query.py", line 794, in filter
    return self._filter_or_exclude(False, *args, **kwargs)
  File "/Library/Python/2.7/site-packages/django/db/models/query.py", line 812, in _filter_or_exclude
    clone.query.add_q(Q(*args, **kwargs))
  File "/Library/Python/2.7/site-packages/django/db/models/sql/query.py", line 1227, in add_q
    clause, _ = self._add_q(q_object, self.used_aliases)
  File "/Library/Python/2.7/site-packages/django/db/models/sql/query.py", line 1253, in _add_q
    allow_joins=allow_joins, split_subq=split_subq,
  File "/Library/Python/2.7/site-packages/django/db/models/sql/query.py", line 1130, in build_filter
    arg, value = filter_expr
TypeError: 'ModelBase' object is not iterable

2017-01-09 03:15:55,931 ERROR 12571 123145310715904 views.py-badge_get:48 Traceback (most recent call last):
  File "/Users/sky-du/workspace/vfastonline/vfast/badge/views.py", line 39, in badge_get
    badge = Badge.objects.get(id=id)
  File "/Library/Python/2.7/site-packages/django/db/models/manager.py", line 85, in manager_method
    return getattr(self.get_queryset(), name)(*args, **kwargs)
  File "/Library/Python/2.7/site-packages/django/db/models/query.py", line 376, in get
    clone = self.filter(*args, **kwargs)
  File "/Library/Python/2.7/site-packages/django/db/models/query.py", line 794, in filter
    return self._filter_or_exclude(False, *args, **kwargs)
  File "/Library/Python/2.7/site-packages/django/db/models/query.py", line 812, in _filter_or_exclude
    clone.query.add_q(Q(*args, **kwargs))
  File "/Library/Python/2.7/site-packages/django/db/models/sql/query.py", line 1227, in add_q
    clause, _ = self._add_q(q_object, self.used_aliases)
  File "/Library/Python/2.7/site-packages/django/db/models/sql/query.py", line 1253, in _add_q
    allow_joins=allow_joins, split_subq=split_subq,
  File "/Library/Python/2.7/site-packages/django/db/models/sql/query.py", line 1130, in build_filter
    arg, value = filter_expr
TypeError: 'ModelBase' object is not iterable

2017-01-09 03:15:57,677 ERROR 12582 123145310715904 views.py-badge_get:48 Traceback (most recent call last):
  File "/Users/sky-du/workspace/vfastonline/vfast/badge/views.py", line 45, in badge_get
    print badge.cratetime
AttributeError: 'Badge' object has no attribute 'cratetime'

2017-01-09 03:15:58,640 ERROR 12582 123145314922496 views.py-badge_get:48 Traceback (most recent call last):
  File "/Users/sky-du/workspace/vfastonline/vfast/badge/views.py", line 45, in badge_get
    print badge.cratetime
AttributeError: 'Badge' object has no attribute 'cratetime'

2017-01-09 03:16:16,467 ERROR 12582 123145310715904 views.py-badge_get:48 Traceback (most recent call last):
  File "/Users/sky-du/workspace/vfastonline/vfast/badge/views.py", line 45, in badge_get
    print badge.createtime
AttributeError: 'Badge' object has no attribute 'cratetime'

2017-01-09 03:16:17,243 ERROR 12582 123145314922496 views.py-badge_get:48 Traceback (most recent call last):
  File "/Users/sky-du/workspace/vfastonline/vfast/badge/views.py", line 45, in badge_get
    print badge.createtime
AttributeError: 'Badge' object has no attribute 'cratetime'

2017-01-09 03:21:54,428 ERROR 12633 123145310715904 views.py-badge_get:45 Traceback (most recent call last):
  File "/Users/sky-du/workspace/vfastonline/vfast/badge/views.py", line 42, in badge_get
    badge = Badge.objects.get(badgename=badgename)
  File "/Library/Python/2.7/site-packages/django/db/models/manager.py", line 85, in manager_method
    return getattr(self.get_queryset(), name)(*args, **kwargs)
  File "/Library/Python/2.7/site-packages/django/db/models/query.py", line 389, in get
    (self.model._meta.object_name, num)
MultipleObjectsReturned: get() returned more than one Badge -- it returned 2!

2017-01-09 03:33:16,168 WARNING 12770 123145310715904 base.py-get_response:152 Not Found: /vcourse/test
2017-01-09 03:38:32,352 ERROR 12770 123145310715904 exception.py-handle_uncaught_exception:124 Internal Server Error: /course/courseadd
Traceback (most recent call last):
  File "/Library/Python/2.7/site-packages/django/core/handlers/exception.py", line 39, in inner
    response = get_response(request)
  File "/Library/Python/2.7/site-packages/django/core/handlers/base.py", line 198, in _get_response
    "returned None instead." % (callback.__module__, view_name)
ValueError: The view vcourse.views.course_add didn't return an HttpResponse object. It returned None instead.
2017-01-09 05:40:56,126 WARNING 12979 123145310715904 base.py-get_response:152 Not Found: /admin
2017-01-09 05:41:15,172 WARNING 12979 123145310715904 base.py-get_response:152 Not Found: /admin
2017-01-09 05:41:16,085 WARNING 12979 123145314922496 base.py-get_response:152 Not Found: /admin
2017-01-09 05:42:41,058 WARNING 13251 123145310715904 base.py-get_response:152 Not Found: /admin
2017-01-09 05:45:36,672 WARNING 13295 123145319129088 base.py-get_response:152 Not Found: /img/meizitu_eCUubjt.jpg
2017-01-09 05:45:43,214 WARNING 13295 123145310715904 base.py-get_response:152 Not Found: /media/img/meizitu_eCUubjt.jpg
2017-01-09 06:16:06,579 ERROR 13630 123145310715904 views.py-course_add:38 Traceback (most recent call last):
  File "/Users/sky-du/workspace/vfastonline/vfast/vcourse/views.py", line 30, in course_add
    typefunc = TypeFunc.objects.get(id=type_func)
  File "/Library/Python/2.7/site-packages/django/db/models/manager.py", line 85, in manager_method
    return getattr(self.get_queryset(), name)(*args, **kwargs)
  File "/Library/Python/2.7/site-packages/django/db/models/query.py", line 376, in get
    clone = self.filter(*args, **kwargs)
  File "/Library/Python/2.7/site-packages/django/db/models/query.py", line 794, in filter
    return self._filter_or_exclude(False, *args, **kwargs)
  File "/Library/Python/2.7/site-packages/django/db/models/query.py", line 812, in _filter_or_exclude
    clone.query.add_q(Q(*args, **kwargs))
  File "/Library/Python/2.7/site-packages/django/db/models/sql/query.py", line 1227, in add_q
    clause, _ = self._add_q(q_object, self.used_aliases)
  File "/Library/Python/2.7/site-packages/django/db/models/sql/query.py", line 1253, in _add_q
    allow_joins=allow_joins, split_subq=split_subq,
  File "/Library/Python/2.7/site-packages/django/db/models/sql/query.py", line 1187, in build_filter
    condition = self.build_lookup(lookups, col, value)
  File "/Library/Python/2.7/site-packages/django/db/models/sql/query.py", line 1083, in build_lookup
    return final_lookup(lhs, rhs)
  File "/Library/Python/2.7/site-packages/django/db/models/lookups.py", line 19, in __init__
    self.rhs = self.get_prep_lookup()
  File "/Library/Python/2.7/site-packages/django/db/models/lookups.py", line 59, in get_prep_lookup
    return self.lhs.output_field.get_prep_value(self.rhs)
  File "/Library/Python/2.7/site-packages/django/db/models/fields/__init__.py", line 946, in get_prep_value
    return int(value)
ValueError: invalid literal for int() with base 10: ''

2017-01-09 06:16:52,411 ERROR 13630 123145310715904 views.py-course_add:38 Traceback (most recent call last):
  File "/Users/sky-du/workspace/vfastonline/vfast/vcourse/views.py", line 30, in course_add
    typefunc = TypeFunc.objects.get(id=type_func)
  File "/Library/Python/2.7/site-packages/django/db/models/manager.py", line 85, in manager_method
    return getattr(self.get_queryset(), name)(*args, **kwargs)
  File "/Library/Python/2.7/site-packages/django/db/models/query.py", line 376, in get
    clone = self.filter(*args, **kwargs)
  File "/Library/Python/2.7/site-packages/django/db/models/query.py", line 794, in filter
    return self._filter_or_exclude(False, *args, **kwargs)
  File "/Library/Python/2.7/site-packages/django/db/models/query.py", line 812, in _filter_or_exclude
    clone.query.add_q(Q(*args, **kwargs))
  File "/Library/Python/2.7/site-packages/django/db/models/sql/query.py", line 1227, in add_q
    clause, _ = self._add_q(q_object, self.used_aliases)
  File "/Library/Python/2.7/site-packages/django/db/models/sql/query.py", line 1253, in _add_q
    allow_joins=allow_joins, split_subq=split_subq,
  File "/Library/Python/2.7/site-packages/django/db/models/sql/query.py", line 1187, in build_filter
    condition = self.build_lookup(lookups, col, value)
  File "/Library/Python/2.7/site-packages/django/db/models/sql/query.py", line 1083, in build_lookup
    return final_lookup(lhs, rhs)
  File "/Library/Python/2.7/site-packages/django/db/models/lookups.py", line 19, in __init__
    self.rhs = self.get_prep_lookup()
  File "/Library/Python/2.7/site-packages/django/db/models/lookups.py", line 59, in get_prep_lookup
    return self.lhs.output_field.get_prep_value(self.rhs)
  File "/Library/Python/2.7/site-packages/django/db/models/fields/__init__.py", line 946, in get_prep_value
    return int(value)
ValueError: invalid literal for int() with base 10: ''

2017-01-09 06:18:52,124 ERROR 13655 123145310715904 views.py-course_add:41 Traceback (most recent call last):
  File "/Users/sky-du/workspace/vfastonline/vfast/vcourse/views.py", line 32, in course_add
    typefunc = TypeFunc.objects.get(id=type_func)
  File "/Library/Python/2.7/site-packages/django/db/models/manager.py", line 85, in manager_method
    return getattr(self.get_queryset(), name)(*args, **kwargs)
  File "/Library/Python/2.7/site-packages/django/db/models/query.py", line 376, in get
    clone = self.filter(*args, **kwargs)
  File "/Library/Python/2.7/site-packages/django/db/models/query.py", line 794, in filter
    return self._filter_or_exclude(False, *args, **kwargs)
  File "/Library/Python/2.7/site-packages/django/db/models/query.py", line 812, in _filter_or_exclude
    clone.query.add_q(Q(*args, **kwargs))
  File "/Library/Python/2.7/site-packages/django/db/models/sql/query.py", line 1227, in add_q
    clause, _ = self._add_q(q_object, self.used_aliases)
  File "/Library/Python/2.7/site-packages/django/db/models/sql/query.py", line 1253, in _add_q
    allow_joins=allow_joins, split_subq=split_subq,
  File "/Library/Python/2.7/site-packages/django/db/models/sql/query.py", line 1187, in build_filter
    condition = self.build_lookup(lookups, col, value)
  File "/Library/Python/2.7/site-packages/django/db/models/sql/query.py", line 1083, in build_lookup
    return final_lookup(lhs, rhs)
  File "/Library/Python/2.7/site-packages/django/db/models/lookups.py", line 19, in __init__
    self.rhs = self.get_prep_lookup()
  File "/Library/Python/2.7/site-packages/django/db/models/lookups.py", line 59, in get_prep_lookup
    return self.lhs.output_field.get_prep_value(self.rhs)
  File "/Library/Python/2.7/site-packages/django/db/models/fields/__init__.py", line 946, in get_prep_value
    return int(value)
ValueError: invalid literal for int() with base 10: ''

2017-01-09 06:20:03,710 ERROR 13655 123145310715904 views.py-course_add:41 Traceback (most recent call last):
  File "/Users/sky-du/workspace/vfastonline/vfast/vcourse/views.py", line 37, in course_add
    subscibe=subscibe, type_func=typefunc, type_lang=typelang)
UnboundLocalError: local variable 'typefunc' referenced before assignment

2017-01-09 06:20:47,409 ERROR 13680 123145310715904 views.py-course_add:42 Traceback (most recent call last):
  File "/Users/sky-du/workspace/vfastonline/vfast/vcourse/views.py", line 35, in course_add
    print typefunc, typelang
UnboundLocalError: local variable 'typefunc' referenced before assignment

2017-01-09 06:20:55,276 ERROR 13680 123145310715904 views.py-course_add:42 Traceback (most recent call last):
  File "/Users/sky-du/workspace/vfastonline/vfast/vcourse/views.py", line 35, in course_add
    print typefunc, typelang
UnboundLocalError: local variable 'typefunc' referenced before assignment

2017-01-09 06:21:03,452 ERROR 13685 123145310715904 views.py-course_add:43 Traceback (most recent call last):
  File "/Users/sky-du/workspace/vfastonline/vfast/vcourse/views.py", line 35, in course_add
    print typefunc, typelang
UnboundLocalError: local variable 'typefunc' referenced before assignment

2017-01-09 06:22:41,018 ERROR 13705 123145310715904 views.py-course_add:46 Traceback (most recent call last):
  File "/Users/sky-du/workspace/vfastonline/vfast/vcourse/views.py", line 42, in course_add
    subscibe=subscibe, type_func=typefunc, type_lang=typelang)
  File "/Library/Python/2.7/site-packages/django/db/models/manager.py", line 85, in manager_method
    return getattr(self.get_queryset(), name)(*args, **kwargs)
  File "/Library/Python/2.7/site-packages/django/db/models/query.py", line 397, in create
    obj = self.model(**kwargs)
  File "/Library/Python/2.7/site-packages/django/db/models/base.py", line 537, in __init__
    setattr(self, field.name, rel_obj)
  File "/Library/Python/2.7/site-packages/django/db/models/fields/related_descriptors.py", line 211, in __set__
    self.field.remote_field.model._meta.object_name,
ValueError: Cannot assign "' '": "Course.type_lang" must be a "TypeProgram" instance.

2017-01-09 06:43:03,182 WARNING 13880 123145314922496 base.py-get_response:152 Not Found: /favicon.ico
2017-01-09 06:46:14,291 ERROR 13980 123145310715904 views.py-course_add:42 Traceback (most recent call last):
  File "/Users/sky-du/workspace/vfastonline/vfast/vcourse/views.py", line 37, in course_add
    subscibe=subscibe, type_func=typefunc, type_lang=typelang)
  File "/Library/Python/2.7/site-packages/django/db/models/manager.py", line 85, in manager_method
    return getattr(self.get_queryset(), name)(*args, **kwargs)
  File "/Library/Python/2.7/site-packages/django/db/models/query.py", line 399, in create
    obj.save(force_insert=True, using=self.db)
  File "/Library/Python/2.7/site-packages/django/db/models/base.py", line 796, in save
    force_update=force_update, update_fields=update_fields)
  File "/Library/Python/2.7/site-packages/django/db/models/base.py", line 824, in save_base
    updated = self._save_table(raw, cls, force_insert, force_update, using, update_fields)
  File "/Library/Python/2.7/site-packages/django/db/models/base.py", line 908, in _save_table
    result = self._do_insert(cls._base_manager, using, fields, update_pk, raw)
  File "/Library/Python/2.7/site-packages/django/db/models/base.py", line 947, in _do_insert
    using=using, raw=raw)
  File "/Library/Python/2.7/site-packages/django/db/models/manager.py", line 85, in manager_method
    return getattr(self.get_queryset(), name)(*args, **kwargs)
  File "/Library/Python/2.7/site-packages/django/db/models/query.py", line 1043, in _insert
    return query.get_compiler(using=using).execute_sql(return_id)
  File "/Library/Python/2.7/site-packages/django/db/models/sql/compiler.py", line 1053, in execute_sql
    for sql, params in self.as_sql():
  File "/Library/Python/2.7/site-packages/django/db/models/sql/compiler.py", line 1006, in as_sql
    for obj in self.query.objs
  File "/Library/Python/2.7/site-packages/django/db/models/sql/compiler.py", line 945, in prepare_value
    value = field.get_db_prep_save(value, connection=self.connection)
  File "/Library/Python/2.7/site-packages/django/db/models/fields/__init__.py", line 755, in get_db_prep_save
    prepared=False)
  File "/Library/Python/2.7/site-packages/django/db/models/fields/__init__.py", line 747, in get_db_prep_value
    value = self.get_prep_value(value)
  File "/Library/Python/2.7/site-packages/django/db/models/fields/__init__.py", line 1832, in get_prep_value
    return int(value)
ValueError: invalid literal for int() with base 10: ''

2017-01-09 06:46:23,373 ERROR 13980 123145310715904 views.py-course_add:42 Traceback (most recent call last):
  File "/Users/sky-du/workspace/vfastonline/vfast/vcourse/views.py", line 37, in course_add
    subscibe=subscibe, type_func=typefunc, type_lang=typelang)
  File "/Library/Python/2.7/site-packages/django/db/models/manager.py", line 85, in manager_method
    return getattr(self.get_queryset(), name)(*args, **kwargs)
  File "/Library/Python/2.7/site-packages/django/db/models/query.py", line 399, in create
    obj.save(force_insert=True, using=self.db)
  File "/Library/Python/2.7/site-packages/django/db/models/base.py", line 796, in save
    force_update=force_update, update_fields=update_fields)
  File "/Library/Python/2.7/site-packages/django/db/models/base.py", line 824, in save_base
    updated = self._save_table(raw, cls, force_insert, force_update, using, update_fields)
  File "/Library/Python/2.7/site-packages/django/db/models/base.py", line 908, in _save_table
    result = self._do_insert(cls._base_manager, using, fields, update_pk, raw)
  File "/Library/Python/2.7/site-packages/django/db/models/base.py", line 947, in _do_insert
    using=using, raw=raw)
  File "/Library/Python/2.7/site-packages/django/db/models/manager.py", line 85, in manager_method
    return getattr(self.get_queryset(), name)(*args, **kwargs)
  File "/Library/Python/2.7/site-packages/django/db/models/query.py", line 1043, in _insert
    return query.get_compiler(using=using).execute_sql(return_id)
  File "/Library/Python/2.7/site-packages/django/db/models/sql/compiler.py", line 1053, in execute_sql
    for sql, params in self.as_sql():
  File "/Library/Python/2.7/site-packages/django/db/models/sql/compiler.py", line 1006, in as_sql
    for obj in self.query.objs
  File "/Library/Python/2.7/site-packages/django/db/models/sql/compiler.py", line 945, in prepare_value
    value = field.get_db_prep_save(value, connection=self.connection)
  File "/Library/Python/2.7/site-packages/django/db/models/fields/__init__.py", line 755, in get_db_prep_save
    prepared=False)
  File "/Library/Python/2.7/site-packages/django/db/models/fields/__init__.py", line 747, in get_db_prep_value
    value = self.get_prep_value(value)
  File "/Library/Python/2.7/site-packages/django/db/models/fields/__init__.py", line 1832, in get_prep_value
    return int(value)
ValueError: invalid literal for int() with base 10: ''

2017-01-09 06:47:24,708 ERROR 13994 123145319129088 views.py-course_add:43 Traceback (most recent call last):
  File "/Users/sky-du/workspace/vfastonline/vfast/vcourse/views.py", line 38, in course_add
    subscibe=subscibe, type_func=typefunc, type_lang=typelang)
  File "/Library/Python/2.7/site-packages/django/db/models/manager.py", line 85, in manager_method
    return getattr(self.get_queryset(), name)(*args, **kwargs)
  File "/Library/Python/2.7/site-packages/django/db/models/query.py", line 399, in create
    obj.save(force_insert=True, using=self.db)
  File "/Library/Python/2.7/site-packages/django/db/models/base.py", line 796, in save
    force_update=force_update, update_fields=update_fields)
  File "/Library/Python/2.7/site-packages/django/db/models/base.py", line 824, in save_base
    updated = self._save_table(raw, cls, force_insert, force_update, using, update_fields)
  File "/Library/Python/2.7/site-packages/django/db/models/base.py", line 908, in _save_table
    result = self._do_insert(cls._base_manager, using, fields, update_pk, raw)
  File "/Library/Python/2.7/site-packages/django/db/models/base.py", line 947, in _do_insert
    using=using, raw=raw)
  File "/Library/Python/2.7/site-packages/django/db/models/manager.py", line 85, in manager_method
    return getattr(self.get_queryset(), name)(*args, **kwargs)
  File "/Library/Python/2.7/site-packages/django/db/models/query.py", line 1043, in _insert
    return query.get_compiler(using=using).execute_sql(return_id)
  File "/Library/Python/2.7/site-packages/django/db/models/sql/compiler.py", line 1053, in execute_sql
    for sql, params in self.as_sql():
  File "/Library/Python/2.7/site-packages/django/db/models/sql/compiler.py", line 1006, in as_sql
    for obj in self.query.objs
  File "/Library/Python/2.7/site-packages/django/db/models/sql/compiler.py", line 945, in prepare_value
    value = field.get_db_prep_save(value, connection=self.connection)
  File "/Library/Python/2.7/site-packages/django/db/models/fields/__init__.py", line 755, in get_db_prep_save
    prepared=False)
  File "/Library/Python/2.7/site-packages/django/db/models/fields/__init__.py", line 747, in get_db_prep_value
    value = self.get_prep_value(value)
  File "/Library/Python/2.7/site-packages/django/db/models/fields/__init__.py", line 1832, in get_prep_value
    return int(value)
ValueError: invalid literal for int() with base 10: ''

2017-01-09 06:49:46,035 ERROR 14007 123145310715904 views.py-course_add:43 Traceback (most recent call last):
  File "/Users/sky-du/workspace/vfastonline/vfast/vcourse/views.py", line 38, in course_add
    subscibe=subscibe, type_func=typefunc, type_lang=typelang)
  File "/Library/Python/2.7/site-packages/django/db/models/manager.py", line 85, in manager_method
    return getattr(self.get_queryset(), name)(*args, **kwargs)
  File "/Library/Python/2.7/site-packages/django/db/models/query.py", line 397, in create
    obj = self.model(**kwargs)
  File "/Library/Python/2.7/site-packages/django/db/models/base.py", line 537, in __init__
    setattr(self, field.name, rel_obj)
  File "/Library/Python/2.7/site-packages/django/db/models/fields/related_descriptors.py", line 211, in __set__
    self.field.remote_field.model._meta.object_name,
ValueError: Cannot assign "1": "Course.type_lang" must be a "TypeProgram" instance.

2017-01-09 06:50:30,809 ERROR 14029 123145310715904 views.py-course_add:43 Traceback (most recent call last):
  File "/Users/sky-du/workspace/vfastonline/vfast/vcourse/views.py", line 38, in course_add
    subscibe=subscibe, type_func_id=typefunc, type_lang_id=typelang)
  File "/Library/Python/2.7/site-packages/django/db/models/manager.py", line 85, in manager_method
    return getattr(self.get_queryset(), name)(*args, **kwargs)
  File "/Library/Python/2.7/site-packages/django/db/models/query.py", line 399, in create
    obj.save(force_insert=True, using=self.db)
  File "/Library/Python/2.7/site-packages/django/db/models/base.py", line 796, in save
    force_update=force_update, update_fields=update_fields)
  File "/Library/Python/2.7/site-packages/django/db/models/base.py", line 824, in save_base
    updated = self._save_table(raw, cls, force_insert, force_update, using, update_fields)
  File "/Library/Python/2.7/site-packages/django/db/models/base.py", line 908, in _save_table
    result = self._do_insert(cls._base_manager, using, fields, update_pk, raw)
  File "/Library/Python/2.7/site-packages/django/db/models/base.py", line 947, in _do_insert
    using=using, raw=raw)
  File "/Library/Python/2.7/site-packages/django/db/models/manager.py", line 85, in manager_method
    return getattr(self.get_queryset(), name)(*args, **kwargs)
  File "/Library/Python/2.7/site-packages/django/db/models/query.py", line 1043, in _insert
    return query.get_compiler(using=using).execute_sql(return_id)
  File "/Library/Python/2.7/site-packages/django/db/models/sql/compiler.py", line 1053, in execute_sql
    for sql, params in self.as_sql():
  File "/Library/Python/2.7/site-packages/django/db/models/sql/compiler.py", line 1006, in as_sql
    for obj in self.query.objs
  File "/Library/Python/2.7/site-packages/django/db/models/sql/compiler.py", line 945, in prepare_value
    value = field.get_db_prep_save(value, connection=self.connection)
  File "/Library/Python/2.7/site-packages/django/db/models/fields/__init__.py", line 755, in get_db_prep_save
    prepared=False)
  File "/Library/Python/2.7/site-packages/django/db/models/fields/__init__.py", line 747, in get_db_prep_value
    value = self.get_prep_value(value)
  File "/Library/Python/2.7/site-packages/django/db/models/fields/__init__.py", line 1832, in get_prep_value
    return int(value)
ValueError: invalid literal for int() with base 10: ''

2017-01-09 06:50:39,223 ERROR 14029 123145310715904 views.py-course_add:43 Traceback (most recent call last):
  File "/Users/sky-du/workspace/vfastonline/vfast/vcourse/views.py", line 38, in course_add
    subscibe=subscibe, type_func_id=typefunc, type_lang_id=typelang)
  File "/Library/Python/2.7/site-packages/django/db/models/manager.py", line 85, in manager_method
    return getattr(self.get_queryset(), name)(*args, **kwargs)
  File "/Library/Python/2.7/site-packages/django/db/models/query.py", line 399, in create
    obj.save(force_insert=True, using=self.db)
  File "/Library/Python/2.7/site-packages/django/db/models/base.py", line 796, in save
    force_update=force_update, update_fields=update_fields)
  File "/Library/Python/2.7/site-packages/django/db/models/base.py", line 824, in save_base
    updated = self._save_table(raw, cls, force_insert, force_update, using, update_fields)
  File "/Library/Python/2.7/site-packages/django/db/models/base.py", line 908, in _save_table
    result = self._do_insert(cls._base_manager, using, fields, update_pk, raw)
  File "/Library/Python/2.7/site-packages/django/db/models/base.py", line 947, in _do_insert
    using=using, raw=raw)
  File "/Library/Python/2.7/site-packages/django/db/models/manager.py", line 85, in manager_method
    return getattr(self.get_queryset(), name)(*args, **kwargs)
  File "/Library/Python/2.7/site-packages/django/db/models/query.py", line 1043, in _insert
    return query.get_compiler(using=using).execute_sql(return_id)
  File "/Library/Python/2.7/site-packages/django/db/models/sql/compiler.py", line 1053, in execute_sql
    for sql, params in self.as_sql():
  File "/Library/Python/2.7/site-packages/django/db/models/sql/compiler.py", line 1006, in as_sql
    for obj in self.query.objs
  File "/Library/Python/2.7/site-packages/django/db/models/sql/compiler.py", line 945, in prepare_value
    value = field.get_db_prep_save(value, connection=self.connection)
  File "/Library/Python/2.7/site-packages/django/db/models/fields/__init__.py", line 755, in get_db_prep_save
    prepared=False)
  File "/Library/Python/2.7/site-packages/django/db/models/fields/__init__.py", line 747, in get_db_prep_value
    value = self.get_prep_value(value)
  File "/Library/Python/2.7/site-packages/django/db/models/fields/__init__.py", line 1832, in get_prep_value
    return int(value)
ValueError: invalid literal for int() with base 10: ''

2017-01-09 06:54:51,542 ERROR 14064 123145310715904 views.py-course_add:43 Traceback (most recent call last):
  File "/Users/sky-du/workspace/vfastonline/vfast/vcourse/views.py", line 38, in course_add
    subscibe=subscibe, type_func_id=typefunc, type_lang_id=typelang)
  File "/Library/Python/2.7/site-packages/django/db/models/manager.py", line 85, in manager_method
    return getattr(self.get_queryset(), name)(*args, **kwargs)
  File "/Library/Python/2.7/site-packages/django/db/models/query.py", line 399, in create
    obj.save(force_insert=True, using=self.db)
  File "/Library/Python/2.7/site-packages/django/db/models/base.py", line 796, in save
    force_update=force_update, update_fields=update_fields)
  File "/Library/Python/2.7/site-packages/django/db/models/base.py", line 824, in save_base
    updated = self._save_table(raw, cls, force_insert, force_update, using, update_fields)
  File "/Library/Python/2.7/site-packages/django/db/models/base.py", line 908, in _save_table
    result = self._do_insert(cls._base_manager, using, fields, update_pk, raw)
  File "/Library/Python/2.7/site-packages/django/db/models/base.py", line 947, in _do_insert
    using=using, raw=raw)
  File "/Library/Python/2.7/site-packages/django/db/models/manager.py", line 85, in manager_method
    return getattr(self.get_queryset(), name)(*args, **kwargs)
  File "/Library/Python/2.7/site-packages/django/db/models/query.py", line 1043, in _insert
    return query.get_compiler(using=using).execute_sql(return_id)
  File "/Library/Python/2.7/site-packages/django/db/models/sql/compiler.py", line 1053, in execute_sql
    for sql, params in self.as_sql():
  File "/Library/Python/2.7/site-packages/django/db/models/sql/compiler.py", line 1006, in as_sql
    for obj in self.query.objs
  File "/Library/Python/2.7/site-packages/django/db/models/sql/compiler.py", line 945, in prepare_value
    value = field.get_db_prep_save(value, connection=self.connection)
  File "/Library/Python/2.7/site-packages/django/db/models/fields/__init__.py", line 755, in get_db_prep_save
    prepared=False)
  File "/Library/Python/2.7/site-packages/django/db/models/fields/__init__.py", line 747, in get_db_prep_value
    value = self.get_prep_value(value)
  File "/Library/Python/2.7/site-packages/django/db/models/fields/__init__.py", line 1832, in get_prep_value
    return int(value)
ValueError: invalid literal for int() with base 10: ''

2017-01-09 06:56:15,699 ERROR 14064 123145310715904 views.py-course_add:43 Traceback (most recent call last):
  File "/Users/sky-du/workspace/vfastonline/vfast/vcourse/views.py", line 38, in course_add
    # subscibe=subscibe, type_func_id=typefunc, type_lang_id=typelang)
  File "/Library/Python/2.7/site-packages/django/db/models/manager.py", line 85, in manager_method
    return getattr(self.get_queryset(), name)(*args, **kwargs)
  File "/Library/Python/2.7/site-packages/django/db/models/query.py", line 399, in create
    obj.save(force_insert=True, using=self.db)
  File "/Library/Python/2.7/site-packages/django/db/models/base.py", line 796, in save
    force_update=force_update, update_fields=update_fields)
  File "/Library/Python/2.7/site-packages/django/db/models/base.py", line 824, in save_base
    updated = self._save_table(raw, cls, force_insert, force_update, using, update_fields)
  File "/Library/Python/2.7/site-packages/django/db/models/base.py", line 908, in _save_table
    result = self._do_insert(cls._base_manager, using, fields, update_pk, raw)
  File "/Library/Python/2.7/site-packages/django/db/models/base.py", line 947, in _do_insert
    using=using, raw=raw)
  File "/Library/Python/2.7/site-packages/django/db/models/manager.py", line 85, in manager_method
    return getattr(self.get_queryset(), name)(*args, **kwargs)
  File "/Library/Python/2.7/site-packages/django/db/models/query.py", line 1043, in _insert
    return query.get_compiler(using=using).execute_sql(return_id)
  File "/Library/Python/2.7/site-packages/django/db/models/sql/compiler.py", line 1053, in execute_sql
    for sql, params in self.as_sql():
  File "/Library/Python/2.7/site-packages/django/db/models/sql/compiler.py", line 1006, in as_sql
    for obj in self.query.objs
  File "/Library/Python/2.7/site-packages/django/db/models/sql/compiler.py", line 945, in prepare_value
    value = field.get_db_prep_save(value, connection=self.connection)
  File "/Library/Python/2.7/site-packages/django/db/models/fields/__init__.py", line 755, in get_db_prep_save
    prepared=False)
  File "/Library/Python/2.7/site-packages/django/db/models/fields/__init__.py", line 747, in get_db_prep_value
    value = self.get_prep_value(value)
  File "/Library/Python/2.7/site-packages/django/db/models/fields/__init__.py", line 1832, in get_prep_value
    return int(value)
ValueError: invalid literal for int() with base 10: ''

2017-01-09 06:56:25,119 ERROR 14078 123145310715904 views.py-course_add:43 Traceback (most recent call last):
  File "/Users/sky-du/workspace/vfastonline/vfast/vcourse/views.py", line 37, in course_add
    pubstatus=pubstatus,)
  File "/Library/Python/2.7/site-packages/django/db/models/manager.py", line 85, in manager_method
    return getattr(self.get_queryset(), name)(*args, **kwargs)
  File "/Library/Python/2.7/site-packages/django/db/models/query.py", line 399, in create
    obj.save(force_insert=True, using=self.db)
  File "/Library/Python/2.7/site-packages/django/db/models/base.py", line 796, in save
    force_update=force_update, update_fields=update_fields)
  File "/Library/Python/2.7/site-packages/django/db/models/base.py", line 824, in save_base
    updated = self._save_table(raw, cls, force_insert, force_update, using, update_fields)
  File "/Library/Python/2.7/site-packages/django/db/models/base.py", line 908, in _save_table
    result = self._do_insert(cls._base_manager, using, fields, update_pk, raw)
  File "/Library/Python/2.7/site-packages/django/db/models/base.py", line 947, in _do_insert
    using=using, raw=raw)
  File "/Library/Python/2.7/site-packages/django/db/models/manager.py", line 85, in manager_method
    return getattr(self.get_queryset(), name)(*args, **kwargs)
  File "/Library/Python/2.7/site-packages/django/db/models/query.py", line 1043, in _insert
    return query.get_compiler(using=using).execute_sql(return_id)
  File "/Library/Python/2.7/site-packages/django/db/models/sql/compiler.py", line 1054, in execute_sql
    cursor.execute(sql, params)
  File "/Library/Python/2.7/site-packages/django/db/backends/utils.py", line 79, in execute
    return super(CursorDebugWrapper, self).execute(sql, params)
  File "/Library/Python/2.7/site-packages/django/db/backends/utils.py", line 64, in execute
    return self.cursor.execute(sql, params)
  File "/Library/Python/2.7/site-packages/django/db/utils.py", line 94, in __exit__
    six.reraise(dj_exc_type, dj_exc_value, traceback)
  File "/Library/Python/2.7/site-packages/django/db/backends/utils.py", line 64, in execute
    return self.cursor.execute(sql, params)
  File "/Library/Python/2.7/site-packages/django/db/backends/sqlite3/base.py", line 337, in execute
    return Database.Cursor.execute(self, query, params)
IntegrityError: NOT NULL constraint failed: vcourse_course.order

2017-01-09 06:58:10,106 ERROR 14094 123145314922496 views.py-course_add:44 Traceback (most recent call last):
  File "/Users/sky-du/workspace/vfastonline/vfast/vcourse/views.py", line 38, in course_add
    pubstatus=pubstatus, order=order)
  File "/Library/Python/2.7/site-packages/django/db/models/manager.py", line 85, in manager_method
    return getattr(self.get_queryset(), name)(*args, **kwargs)
  File "/Library/Python/2.7/site-packages/django/db/models/query.py", line 399, in create
    obj.save(force_insert=True, using=self.db)
  File "/Library/Python/2.7/site-packages/django/db/models/base.py", line 796, in save
    force_update=force_update, update_fields=update_fields)
  File "/Library/Python/2.7/site-packages/django/db/models/base.py", line 824, in save_base
    updated = self._save_table(raw, cls, force_insert, force_update, using, update_fields)
  File "/Library/Python/2.7/site-packages/django/db/models/base.py", line 908, in _save_table
    result = self._do_insert(cls._base_manager, using, fields, update_pk, raw)
  File "/Library/Python/2.7/site-packages/django/db/models/base.py", line 947, in _do_insert
    using=using, raw=raw)
  File "/Library/Python/2.7/site-packages/django/db/models/manager.py", line 85, in manager_method
    return getattr(self.get_queryset(), name)(*args, **kwargs)
  File "/Library/Python/2.7/site-packages/django/db/models/query.py", line 1043, in _insert
    return query.get_compiler(using=using).execute_sql(return_id)
  File "/Library/Python/2.7/site-packages/django/db/models/sql/compiler.py", line 1054, in execute_sql
    cursor.execute(sql, params)
  File "/Library/Python/2.7/site-packages/django/db/backends/utils.py", line 79, in execute
    return super(CursorDebugWrapper, self).execute(sql, params)
  File "/Library/Python/2.7/site-packages/django/db/backends/utils.py", line 64, in execute
    return self.cursor.execute(sql, params)
  File "/Library/Python/2.7/site-packages/django/db/utils.py", line 94, in __exit__
    six.reraise(dj_exc_type, dj_exc_value, traceback)
  File "/Library/Python/2.7/site-packages/django/db/backends/utils.py", line 64, in execute
    return self.cursor.execute(sql, params)
  File "/Library/Python/2.7/site-packages/django/db/backends/sqlite3/base.py", line 337, in execute
    return Database.Cursor.execute(self, query, params)
IntegrityError: NOT NULL constraint failed: vcourse_course.order

2017-01-09 07:00:04,821 ERROR 14120 123145310715904 views.py-course_add:45 Traceback (most recent call last):
  File "/Users/sky-du/workspace/vfastonline/vfast/vcourse/views.py", line 39, in course_add
    pubstatus=pubstatus, order=order)
  File "/Library/Python/2.7/site-packages/django/db/models/manager.py", line 85, in manager_method
    return getattr(self.get_queryset(), name)(*args, **kwargs)
  File "/Library/Python/2.7/site-packages/django/db/models/query.py", line 399, in create
    obj.save(force_insert=True, using=self.db)
  File "/Library/Python/2.7/site-packages/django/db/models/base.py", line 796, in save
    force_update=force_update, update_fields=update_fields)
  File "/Library/Python/2.7/site-packages/django/db/models/base.py", line 824, in save_base
    updated = self._save_table(raw, cls, force_insert, force_update, using, update_fields)
  File "/Library/Python/2.7/site-packages/django/db/models/base.py", line 908, in _save_table
    result = self._do_insert(cls._base_manager, using, fields, update_pk, raw)
  File "/Library/Python/2.7/site-packages/django/db/models/base.py", line 947, in _do_insert
    using=using, raw=raw)
  File "/Library/Python/2.7/site-packages/django/db/models/manager.py", line 85, in manager_method
    return getattr(self.get_queryset(), name)(*args, **kwargs)
  File "/Library/Python/2.7/site-packages/django/db/models/query.py", line 1043, in _insert
    return query.get_compiler(using=using).execute_sql(return_id)
  File "/Library/Python/2.7/site-packages/django/db/models/sql/compiler.py", line 1054, in execute_sql
    cursor.execute(sql, params)
  File "/Library/Python/2.7/site-packages/django/db/backends/utils.py", line 79, in execute
    return super(CursorDebugWrapper, self).execute(sql, params)
  File "/Library/Python/2.7/site-packages/django/db/backends/utils.py", line 64, in execute
    return self.cursor.execute(sql, params)
  File "/Library/Python/2.7/site-packages/django/db/utils.py", line 94, in __exit__
    six.reraise(dj_exc_type, dj_exc_value, traceback)
  File "/Library/Python/2.7/site-packages/django/db/backends/utils.py", line 64, in execute
    return self.cursor.execute(sql, params)
  File "/Library/Python/2.7/site-packages/django/db/backends/sqlite3/base.py", line 337, in execute
    return Database.Cursor.execute(self, query, params)
IntegrityError: NOT NULL constraint failed: vcourse_course.order

2017-01-09 07:02:02,626 ERROR 14136 123145310715904 views.py-course_add:45 Traceback (most recent call last):
  File "/Users/sky-du/workspace/vfastonline/vfast/vcourse/views.py", line 40, in course_add
    subscibe=subscibe, type_func_id=typefunc, type_lang_id=typelang)
  File "/Library/Python/2.7/site-packages/django/db/models/manager.py", line 85, in manager_method
    return getattr(self.get_queryset(), name)(*args, **kwargs)
  File "/Library/Python/2.7/site-packages/django/db/models/query.py", line 399, in create
    obj.save(force_insert=True, using=self.db)
  File "/Library/Python/2.7/site-packages/django/db/models/base.py", line 796, in save
    force_update=force_update, update_fields=update_fields)
  File "/Library/Python/2.7/site-packages/django/db/models/base.py", line 824, in save_base
    updated = self._save_table(raw, cls, force_insert, force_update, using, update_fields)
  File "/Library/Python/2.7/site-packages/django/db/models/base.py", line 908, in _save_table
    result = self._do_insert(cls._base_manager, using, fields, update_pk, raw)
  File "/Library/Python/2.7/site-packages/django/db/models/base.py", line 947, in _do_insert
    using=using, raw=raw)
  File "/Library/Python/2.7/site-packages/django/db/models/manager.py", line 85, in manager_method
    return getattr(self.get_queryset(), name)(*args, **kwargs)
  File "/Library/Python/2.7/site-packages/django/db/models/query.py", line 1043, in _insert
    return query.get_compiler(using=using).execute_sql(return_id)
  File "/Library/Python/2.7/site-packages/django/db/models/sql/compiler.py", line 1054, in execute_sql
    cursor.execute(sql, params)
  File "/Library/Python/2.7/site-packages/django/db/backends/utils.py", line 79, in execute
    return super(CursorDebugWrapper, self).execute(sql, params)
  File "/Library/Python/2.7/site-packages/django/db/backends/utils.py", line 64, in execute
    return self.cursor.execute(sql, params)
  File "/Library/Python/2.7/site-packages/django/db/utils.py", line 94, in __exit__
    six.reraise(dj_exc_type, dj_exc_value, traceback)
  File "/Library/Python/2.7/site-packages/django/db/backends/utils.py", line 64, in execute
    return self.cursor.execute(sql, params)
  File "/Library/Python/2.7/site-packages/django/db/backends/sqlite3/base.py", line 337, in execute
    return Database.Cursor.execute(self, query, params)
IntegrityError: UNIQUE constraint failed: vcourse_course.order

2017-01-09 07:27:45,160 ERROR 14394 123145310715904 views.py-video_add:74 Traceback (most recent call last):
  File "/Users/sky-du/workspace/vfastonline/vfast/vcourse/views.py", line 60, in video_add
    videofile = request.FILES['video']
  File "/Library/Python/2.7/site-packages/django/utils/datastructures.py", line 85, in __getitem__
    raise MultiValueDictKeyError(repr(key))
MultiValueDictKeyError: "'video'"

2017-01-09 07:30:28,988 ERROR 14433 123145310715904 views.py-video_add:76 Traceback (most recent call last):
  File "/Users/sky-du/workspace/vfastonline/vfast/vcourse/views.py", line 63, in video_add
    teacher_note_file = request.FILES['teacher_note']
  File "/Library/Python/2.7/site-packages/django/utils/datastructures.py", line 85, in __getitem__
    raise MultiValueDictKeyError(repr(key))
MultiValueDictKeyError: "'teacher_note'"

2017-01-09 07:30:45,249 ERROR 14440 123145310715904 views.py-video_add:76 Traceback (most recent call last):
  File "/Users/sky-du/workspace/vfastonline/vfast/vcourse/views.py", line 64, in video_add
    teacher_note_file = request.FILES['teacher_note']
  File "/Library/Python/2.7/site-packages/django/utils/datastructures.py", line 85, in __getitem__
    raise MultiValueDictKeyError(repr(key))
MultiValueDictKeyError: "'teacher_note'"

2017-01-09 07:30:58,418 ERROR 14440 123145310715904 views.py-video_add:76 Traceback (most recent call last):
  File "/Users/sky-du/workspace/vfastonline/vfast/vcourse/views.py", line 64, in video_add
    order = request.POST.get('order')
  File "/Library/Python/2.7/site-packages/django/utils/datastructures.py", line 85, in __getitem__
    raise MultiValueDictKeyError(repr(key))
MultiValueDictKeyError: "'teacher_note'"

2017-01-09 07:31:05,739 ERROR 14445 123145310715904 views.py-video_add:77 Traceback (most recent call last):
  File "/Users/sky-du/workspace/vfastonline/vfast/vcourse/views.py", line 65, in video_add
    teacher_note_file = request.FILES['teacher_note']
  File "/Library/Python/2.7/site-packages/django/utils/datastructures.py", line 85, in __getitem__
    raise MultiValueDictKeyError(repr(key))
MultiValueDictKeyError: "'teacher_note'"

2017-01-09 07:38:07,059 ERROR 14509 123145310715904 views.py-video_add:77 Traceback (most recent call last):
  File "/Users/sky-du/workspace/vfastonline/vfast/vcourse/views.py", line 69, in video_add
    teacher_note_file = request.FILES['teacher_note']
  File "/Library/Python/2.7/site-packages/django/utils/datastructures.py", line 85, in __getitem__
    raise MultiValueDictKeyError(repr(key))
MultiValueDictKeyError: "'teacher_note'"

2017-01-09 07:38:16,293 ERROR 14509 123145314922496 views.py-video_add:77 Traceback (most recent call last):
  File "/Users/sky-du/workspace/vfastonline/vfast/vcourse/views.py", line 69, in video_add
    teacher_note_file = request.FILES['teacher_note']
  File "/Library/Python/2.7/site-packages/django/utils/datastructures.py", line 85, in __getitem__
    raise MultiValueDictKeyError(repr(key))
MultiValueDictKeyError: "'teacher_note'"

2017-01-09 07:42:43,693 ERROR 14552 123145310715904 views.py-video_add:78 Traceback (most recent call last):
  File "/Users/sky-du/workspace/vfastonline/vfast/vcourse/views.py", line 69, in video_add
    teacher_note_file = request.FILES['teacher_note']
  File "/Library/Python/2.7/site-packages/django/utils/datastructures.py", line 85, in __getitem__
    raise MultiValueDictKeyError(repr(key))
MultiValueDictKeyError: "'teacher_note'"

2017-01-09 07:46:52,581 ERROR 14607 123145310715904 views.py-video_add:78 Traceback (most recent call last):
  File "/Users/sky-du/workspace/vfastonline/vfast/vcourse/views.py", line 65, in video_add
    teacher = User.objects.get(id=teacherid)
  File "/Library/Python/2.7/site-packages/django/db/models/manager.py", line 85, in manager_method
    return getattr(self.get_queryset(), name)(*args, **kwargs)
  File "/Library/Python/2.7/site-packages/django/db/models/query.py", line 385, in get
    self.model._meta.object_name
DoesNotExist: User matching query does not exist.

2017-01-09 07:54:49,004 WARNING 14678 123145310715904 base.py-get_response:152 Not Found: //media/meizitu_rgcy94b.jpg
2017-01-09 07:54:54,226 WARNING 14678 123145310715904 base.py-get_response:152 Not Found: /media/meizitu_rgcy94b.jpg
2017-01-09 08:10:24,886 ERROR 14819 123145310715904 views.py-badge_add:34 Traceback (most recent call last):
  File "/Users/sky-du/workspace/vfastonline/vfast/badge/views.py", line 25, in badge_add
    dest = open(os.path.join(settings.MEDIA_ROOT, uploaded_file_url))
IOError: [Errno 2] No such file or directory: u'/Users/sky-du/workspace/vfastonline/vfast/media/imgmeizitu.jpg'

2017-01-09 08:10:54,834 ERROR 14825 123145310715904 views.py-badge_add:34 Traceback (most recent call last):
  File "/Users/sky-du/workspace/vfastonline/vfast/badge/views.py", line 28, in badge_add
    dest.write(chunk)
IOError: File not open for writing

2017-01-09 08:18:44,969 ERROR 14909 123145310715904 views.py-video_add:74 Traceback (most recent call last):
  File "/Users/sky-du/workspace/vfastonline/vfast/vcourse/views.py", line 69, in video_add
    teacher_note_file = request.FILES['teacher_note']
  File "/Library/Python/2.7/site-packages/django/utils/datastructures.py", line 85, in __getitem__
    raise MultiValueDictKeyError(repr(key))
MultiValueDictKeyError: "'teacher_note'"

2017-01-09 08:46:50,516 ERROR 15227 123145310715904 views.py-video_add:87 Traceback (most recent call last):
  File "/Users/sky-du/workspace/vfastonline/vfast/vcourse/views.py", line 75, in video_add
    vdest = open(os.path.join(settings.MEDIA_ROOT, 'video/%s/%s' % (day, videofile.name)), 'wb+')
IOError: [Errno 2] No such file or directory: u'/Users/sky-du/workspace/vfastonline/vfast/media/video/20170109/basketball.mp4'

2017-01-09 08:47:29,706 ERROR 15236 123145310715904 views.py-video_add:87 Traceback (most recent call last):
  File "/Users/sky-du/workspace/vfastonline/vfast/vcourse/views.py", line 75, in video_add
    vdest = open(os.path.join(settings.MEDIA_ROOT, 'video/%s/%s' % (day, videofile.name)), 'wb+')
IOError: [Errno 2] No such file or directory: u'/Users/sky-du/workspace/vfastonline/vfast/media/video/20170109/basketball.mp4'

2017-01-09 08:54:13,579 ERROR 15290 123145310715904 views.py-video_add:90 Traceback (most recent call last):
  File "/Users/sky-du/workspace/vfastonline/vfast/vcourse/views.py", line 78, in video_add
    os.system('mkdir -p %s' % os.path.dirname(vdest))
UnboundLocalError: local variable 'vdest' referenced before assignment

2017-01-09 08:57:33,055 ERROR 15334 123145310715904 views.py-video_add:89 Traceback (most recent call last):
  File "/Users/sky-du/workspace/vfastonline/vfast/vcourse/views.py", line 77, in video_add
    vdest = open(os.path.join(vpath, videofile.name))
IOError: [Errno 2] No such file or directory: u'/Users/sky-du/workspace/vfastonline/vfast/media/video/20170109/basketball.mp4'

2017-01-09 08:57:54,751 ERROR 15342 123145310715904 views.py-video_add:89 Traceback (most recent call last):
  File "/Users/sky-du/workspace/vfastonline/vfast/vcourse/views.py", line 80, in video_add
    vdest.write(chunk)
ValueError: I/O operation on closed file

2017-01-09 08:58:34,756 ERROR 15342 123145310715904 views.py-video_add:89 Traceback (most recent call last):
  File "/Users/sky-du/workspace/vfastonline/vfast/vcourse/views.py", line 80, in video_add
    vdest.write(chunk)
ValueError: I/O operation on closed file

2017-01-09 09:00:33,725 ERROR 15365 123145310715904 views.py-video_add:89 Traceback (most recent call last):
  File "/Users/sky-du/workspace/vfastonline/vfast/vcourse/views.py", line 80, in video_add
    vdest.write(chunk)
ValueError: I/O operation on closed file

2017-01-09 09:05:57,648 ERROR 15443 123145310715904 views.py-video_add:94 Traceback (most recent call last):
  File "/Users/sky-du/workspace/vfastonline/vfast/vcourse/views.py", line 86, in video_add
    filename = open(os.path.join(vpath, file.name), 'wb+')
AttributeError: 'NoneType' object has no attribute 'name'

2017-01-09 09:14:57,289 ERROR 15572 123145310715904 views.py-video_add:96 Traceback (most recent call last):
  File "/Users/sky-du/workspace/vfastonline/vfast/vcourse/views.py", line 80, in video_add
    teacher_note = os.path.join('video/%s/%s' % (day, teacher_note_file.name))
AttributeError: 'NoneType' object has no attribute 'name'

2017-01-09 09:28:41,514 ERROR 15714 123145310715904 views.py-video_add:99 Traceback (most recent call last):
  File "/Users/sky-du/workspace/vfastonline/vfast/vcourse/views.py", line 94, in video_add
    courseid=course, teacher=teacher, createtime=createtime)
  File "/Library/Python/2.7/site-packages/django/db/models/manager.py", line 85, in manager_method
    return getattr(self.get_queryset(), name)(*args, **kwargs)
  File "/Library/Python/2.7/site-packages/django/db/models/query.py", line 397, in create
    obj = self.model(**kwargs)
  File "/Library/Python/2.7/site-packages/django/db/models/base.py", line 555, in __init__
    raise TypeError("'%s' is an invalid keyword argument for this function" % list(kwargs)[0])
TypeError: 'videotime' is an invalid keyword argument for this function

2017-01-09 09:29:35,309 ERROR 15714 123145310715904 views.py-video_add:99 Traceback (most recent call last):
  File "/Users/sky-du/workspace/vfastonline/vfast/vcourse/views.py", line 94, in video_add
    courseid=course, teacher=teacher, createtime=createtime)
  File "/Library/Python/2.7/site-packages/django/db/models/manager.py", line 85, in manager_method
    return getattr(self.get_queryset(), name)(*args, **kwargs)
  File "/Library/Python/2.7/site-packages/django/db/models/query.py", line 397, in create
    obj = self.model(**kwargs)
  File "/Library/Python/2.7/site-packages/django/db/models/base.py", line 555, in __init__
    raise TypeError("'%s' is an invalid keyword argument for this function" % list(kwargs)[0])
TypeError: 'videotime' is an invalid keyword argument for this function

2017-01-09 09:31:19,410 ERROR 15751 123145310715904 views.py-video_add:99 Traceback (most recent call last):
  File "/Users/sky-du/workspace/vfastonline/vfast/vcourse/views.py", line 94, in video_add
    courseid=course, teacher=teacher, createtime=createtime)
  File "/Library/Python/2.7/site-packages/django/db/models/manager.py", line 85, in manager_method
    return getattr(self.get_queryset(), name)(*args, **kwargs)
  File "/Library/Python/2.7/site-packages/django/db/models/query.py", line 397, in create
    obj = self.model(**kwargs)
  File "/Library/Python/2.7/site-packages/django/db/models/base.py", line 555, in __init__
    raise TypeError("'%s' is an invalid keyword argument for this function" % list(kwargs)[0])
TypeError: 'videotime' is an invalid keyword argument for this function

2017-01-09 09:31:50,398 ERROR 15761 123145310715904 views.py-video_add:99 Traceback (most recent call last):
  File "/Users/sky-du/workspace/vfastonline/vfast/vcourse/views.py", line 94, in video_add
    courseid=course, teacher=teacher, createtime=createtime)
  File "/Library/Python/2.7/site-packages/django/db/models/manager.py", line 85, in manager_method
    return getattr(self.get_queryset(), name)(*args, **kwargs)
  File "/Library/Python/2.7/site-packages/django/db/models/query.py", line 397, in create
    obj = self.model(**kwargs)
  File "/Library/Python/2.7/site-packages/django/db/models/base.py", line 555, in __init__
    raise TypeError("'%s' is an invalid keyword argument for this function" % list(kwargs)[0])
TypeError: 'videotime' is an invalid keyword argument for this function

2017-01-09 09:32:10,232 ERROR 15768 123145310715904 views.py-video_add:99 Traceback (most recent call last):
  File "/Users/sky-du/workspace/vfastonline/vfast/vcourse/views.py", line 94, in video_add
    courseid=course, teacher=teacher, createtime=createtime)
  File "/Library/Python/2.7/site-packages/django/db/models/manager.py", line 85, in manager_method
    return getattr(self.get_queryset(), name)(*args, **kwargs)
  File "/Library/Python/2.7/site-packages/django/db/models/query.py", line 397, in create
    obj = self.model(**kwargs)
  File "/Library/Python/2.7/site-packages/django/db/models/base.py", line 555, in __init__
    raise TypeError("'%s' is an invalid keyword argument for this function" % list(kwargs)[0])
TypeError: 'videotime' is an invalid keyword argument for this function

2017-01-09 09:32:16,293 ERROR 15768 123145310715904 views.py-video_add:99 Traceback (most recent call last):
  File "/Users/sky-du/workspace/vfastonline/vfast/vcourse/views.py", line 94, in video_add
    courseid=course, teacher=teacher, createtime=createtime)
  File "/Library/Python/2.7/site-packages/django/db/models/manager.py", line 85, in manager_method
    return getattr(self.get_queryset(), name)(*args, **kwargs)
  File "/Library/Python/2.7/site-packages/django/db/models/query.py", line 397, in create
    obj = self.model(**kwargs)
  File "/Library/Python/2.7/site-packages/django/db/models/base.py", line 555, in __init__
    raise TypeError("'%s' is an invalid keyword argument for this function" % list(kwargs)[0])
TypeError: 'videotime' is an invalid keyword argument for this function

2017-01-09 09:32:21,549 ERROR 15768 123145310715904 views.py-video_add:99 Traceback (most recent call last):
  File "/Users/sky-du/workspace/vfastonline/vfast/vcourse/views.py", line 94, in video_add
    courseid=course, teacher=teacher, createtime=createtime)
  File "/Library/Python/2.7/site-packages/django/db/models/manager.py", line 85, in manager_method
    return getattr(self.get_queryset(), name)(*args, **kwargs)
  File "/Library/Python/2.7/site-packages/django/db/models/query.py", line 397, in create
    obj = self.model(**kwargs)
  File "/Library/Python/2.7/site-packages/django/db/models/base.py", line 555, in __init__
    raise TypeError("'%s' is an invalid keyword argument for this function" % list(kwargs)[0])
TypeError: 'videotime' is an invalid keyword argument for this function

2017-01-09 09:34:12,477 ERROR 15786 123145310715904 views.py-video_add:100 Traceback (most recent call last):
  File "/Users/sky-du/workspace/vfastonline/vfast/vcourse/views.py", line 95, in video_add
    courseid=course, teacher=teacher, createtime=createtime)
  File "/Library/Python/2.7/site-packages/django/db/models/manager.py", line 85, in manager_method
    return getattr(self.get_queryset(), name)(*args, **kwargs)
  File "/Library/Python/2.7/site-packages/django/db/models/query.py", line 397, in create
    obj = self.model(**kwargs)
  File "/Library/Python/2.7/site-packages/django/db/models/base.py", line 555, in __init__
    raise TypeError("'%s' is an invalid keyword argument for this function" % list(kwargs)[0])
TypeError: 'courseid' is an invalid keyword argument for this function

2017-01-09 09:36:14,923 ERROR 15816 123145310715904 views.py-video_add:101 Traceback (most recent call last):
  File "/Users/sky-du/workspace/vfastonline/vfast/vcourse/views.py", line 96, in video_add
    courseid=course, teacher=teacher, createtime=createtime)
  File "/Library/Python/2.7/site-packages/django/db/models/manager.py", line 85, in manager_method
    return getattr(self.get_queryset(), name)(*args, **kwargs)
  File "/Library/Python/2.7/site-packages/django/db/models/query.py", line 397, in create
    obj = self.model(**kwargs)
  File "/Library/Python/2.7/site-packages/django/db/models/base.py", line 555, in __init__
    raise TypeError("'%s' is an invalid keyword argument for this function" % list(kwargs)[0])
TypeError: 'courseid' is an invalid keyword argument for this function

2017-01-09 09:37:22,703 ERROR 15830 123145310715904 views.py-video_add:101 Traceback (most recent call last):
  File "/Users/sky-du/workspace/vfastonline/vfast/vcourse/views.py", line 96, in video_add
    courseid=course, teacher=teacher, createtime=createtime)
  File "/Library/Python/2.7/site-packages/django/db/models/manager.py", line 85, in manager_method
    return getattr(self.get_queryset(), name)(*args, **kwargs)
  File "/Library/Python/2.7/site-packages/django/db/models/query.py", line 399, in create
    obj.save(force_insert=True, using=self.db)
  File "/Library/Python/2.7/site-packages/django/db/models/base.py", line 796, in save
    force_update=force_update, update_fields=update_fields)
  File "/Library/Python/2.7/site-packages/django/db/models/base.py", line 824, in save_base
    updated = self._save_table(raw, cls, force_insert, force_update, using, update_fields)
  File "/Library/Python/2.7/site-packages/django/db/models/base.py", line 908, in _save_table
    result = self._do_insert(cls._base_manager, using, fields, update_pk, raw)
  File "/Library/Python/2.7/site-packages/django/db/models/base.py", line 947, in _do_insert
    using=using, raw=raw)
  File "/Library/Python/2.7/site-packages/django/db/models/manager.py", line 85, in manager_method
    return getattr(self.get_queryset(), name)(*args, **kwargs)
  File "/Library/Python/2.7/site-packages/django/db/models/query.py", line 1043, in _insert
    return query.get_compiler(using=using).execute_sql(return_id)
  File "/Library/Python/2.7/site-packages/django/db/models/sql/compiler.py", line 1054, in execute_sql
    cursor.execute(sql, params)
  File "/Library/Python/2.7/site-packages/django/db/backends/utils.py", line 79, in execute
    return super(CursorDebugWrapper, self).execute(sql, params)
  File "/Library/Python/2.7/site-packages/django/db/backends/utils.py", line 64, in execute
    return self.cursor.execute(sql, params)
  File "/Library/Python/2.7/site-packages/django/db/utils.py", line 94, in __exit__
    six.reraise(dj_exc_type, dj_exc_value, traceback)
  File "/Library/Python/2.7/site-packages/django/db/backends/utils.py", line 64, in execute
    return self.cursor.execute(sql, params)
  File "/Library/Python/2.7/site-packages/django/db/backends/sqlite3/base.py", line 337, in execute
    return Database.Cursor.execute(self, query, params)
IntegrityError: NOT NULL constraint failed: vcourse_video.videotime

2017-01-09 09:37:24,514 ERROR 15830 123145314922496 views.py-video_add:101 Traceback (most recent call last):
  File "/Users/sky-du/workspace/vfastonline/vfast/vcourse/views.py", line 96, in video_add
    courseid=course, teacher=teacher, createtime=createtime)
  File "/Library/Python/2.7/site-packages/django/db/models/manager.py", line 85, in manager_method
    return getattr(self.get_queryset(), name)(*args, **kwargs)
  File "/Library/Python/2.7/site-packages/django/db/models/query.py", line 399, in create
    obj.save(force_insert=True, using=self.db)
  File "/Library/Python/2.7/site-packages/django/db/models/base.py", line 796, in save
    force_update=force_update, update_fields=update_fields)
  File "/Library/Python/2.7/site-packages/django/db/models/base.py", line 824, in save_base
    updated = self._save_table(raw, cls, force_insert, force_update, using, update_fields)
  File "/Library/Python/2.7/site-packages/django/db/models/base.py", line 908, in _save_table
    result = self._do_insert(cls._base_manager, using, fields, update_pk, raw)
  File "/Library/Python/2.7/site-packages/django/db/models/base.py", line 947, in _do_insert
    using=using, raw=raw)
  File "/Library/Python/2.7/site-packages/django/db/models/manager.py", line 85, in manager_method
    return getattr(self.get_queryset(), name)(*args, **kwargs)
  File "/Library/Python/2.7/site-packages/django/db/models/query.py", line 1043, in _insert
    return query.get_compiler(using=using).execute_sql(return_id)
  File "/Library/Python/2.7/site-packages/django/db/models/sql/compiler.py", line 1054, in execute_sql
    cursor.execute(sql, params)
  File "/Library/Python/2.7/site-packages/django/db/backends/utils.py", line 79, in execute
    return super(CursorDebugWrapper, self).execute(sql, params)
  File "/Library/Python/2.7/site-packages/django/db/backends/utils.py", line 64, in execute
    return self.cursor.execute(sql, params)
  File "/Library/Python/2.7/site-packages/django/db/utils.py", line 94, in __exit__
    six.reraise(dj_exc_type, dj_exc_value, traceback)
  File "/Library/Python/2.7/site-packages/django/db/backends/utils.py", line 64, in execute
    return self.cursor.execute(sql, params)
  File "/Library/Python/2.7/site-packages/django/db/backends/sqlite3/base.py", line 337, in execute
    return Database.Cursor.execute(self, query, params)
IntegrityError: NOT NULL constraint failed: vcourse_video.videotime

2017-01-09 11:46:04,610 ERROR 16628 123145310715904 views.py-path_add:148 Traceback (most recent call last):
  File "/Users/sky-du/workspace/vfastonline/vfast/vcourse/views.py", line 140, in path_add
    sql.save()
  File "/Library/Python/2.7/site-packages/django/db/models/base.py", line 796, in save
    force_update=force_update, update_fields=update_fields)
  File "/Library/Python/2.7/site-packages/django/db/models/base.py", line 824, in save_base
    updated = self._save_table(raw, cls, force_insert, force_update, using, update_fields)
  File "/Library/Python/2.7/site-packages/django/db/models/base.py", line 908, in _save_table
    result = self._do_insert(cls._base_manager, using, fields, update_pk, raw)
  File "/Library/Python/2.7/site-packages/django/db/models/base.py", line 947, in _do_insert
    using=using, raw=raw)
  File "/Library/Python/2.7/site-packages/django/db/models/manager.py", line 85, in manager_method
    return getattr(self.get_queryset(), name)(*args, **kwargs)
  File "/Library/Python/2.7/site-packages/django/db/models/query.py", line 1043, in _insert
    return query.get_compiler(using=using).execute_sql(return_id)
  File "/Library/Python/2.7/site-packages/django/db/models/sql/compiler.py", line 1053, in execute_sql
    for sql, params in self.as_sql():
  File "/Library/Python/2.7/site-packages/django/db/models/sql/compiler.py", line 1006, in as_sql
    for obj in self.query.objs
  File "/Library/Python/2.7/site-packages/django/db/models/sql/compiler.py", line 945, in prepare_value
    value = field.get_db_prep_save(value, connection=self.connection)
  File "/Library/Python/2.7/site-packages/django/db/models/fields/__init__.py", line 755, in get_db_prep_save
    prepared=False)
  File "/Library/Python/2.7/site-packages/django/db/models/fields/__init__.py", line 1280, in get_db_prep_value
    value = self.get_prep_value(value)
  File "/Library/Python/2.7/site-packages/django/db/models/fields/__init__.py", line 1275, in get_prep_value
    return self.to_python(value)
  File "/Library/Python/2.7/site-packages/django/db/models/fields/__init__.py", line 1250, in to_python
    params={'value': value},
ValidationError: [u"'1' value has an invalid date format. It must be in YYYY-MM-DD format."]

2017-01-09 12:01:40,738 ERROR 16695 123145310715904 views.py-video_add:98 Traceback (most recent call last):
  File "/Users/sky-du/workspace/vfastonline/vfast/vcourse/views.py", line 67, in video_add
    teacher = User.objects.get(id=teacherid)
  File "/Library/Python/2.7/site-packages/django/db/models/manager.py", line 85, in manager_method
    return getattr(self.get_queryset(), name)(*args, **kwargs)
  File "/Library/Python/2.7/site-packages/django/db/models/query.py", line 376, in get
    clone = self.filter(*args, **kwargs)
  File "/Library/Python/2.7/site-packages/django/db/models/query.py", line 794, in filter
    return self._filter_or_exclude(False, *args, **kwargs)
  File "/Library/Python/2.7/site-packages/django/db/models/query.py", line 812, in _filter_or_exclude
    clone.query.add_q(Q(*args, **kwargs))
  File "/Library/Python/2.7/site-packages/django/db/models/sql/query.py", line 1227, in add_q
    clause, _ = self._add_q(q_object, self.used_aliases)
  File "/Library/Python/2.7/site-packages/django/db/models/sql/query.py", line 1253, in _add_q
    allow_joins=allow_joins, split_subq=split_subq,
  File "/Library/Python/2.7/site-packages/django/db/models/sql/query.py", line 1187, in build_filter
    condition = self.build_lookup(lookups, col, value)
  File "/Library/Python/2.7/site-packages/django/db/models/sql/query.py", line 1083, in build_lookup
    return final_lookup(lhs, rhs)
  File "/Library/Python/2.7/site-packages/django/db/models/lookups.py", line 19, in __init__
    self.rhs = self.get_prep_lookup()
  File "/Library/Python/2.7/site-packages/django/db/models/lookups.py", line 59, in get_prep_lookup
    return self.lhs.output_field.get_prep_value(self.rhs)
  File "/Library/Python/2.7/site-packages/django/db/models/fields/__init__.py", line 946, in get_prep_value
    return int(value)
ValueError: invalid literal for int() with base 10: ''

2017-01-09 12:26:24,277 ERROR 17096 123145310715904 views.py-getvideo:161 Traceback (most recent call last):
  File "/Users/sky-du/workspace/vfastonline/vfast/vcourse/views.py", line 157, in getvideo
    videos = get_results(Video)
  File "/Users/sky-du/workspace/vfastonline/vfast/vfast/api.py", line 123, in get_results
    results = models.objects.filter().values('id', 'result')
  File "/Library/Python/2.7/site-packages/django/db/models/query.py", line 717, in values
    clone = self._values(*fields)
  File "/Library/Python/2.7/site-packages/django/db/models/query.py", line 712, in _values
    query.add_fields(field_names, True)
  File "/Library/Python/2.7/site-packages/django/db/models/sql/query.py", line 1644, in add_fields
    "Choices are: %s" % (name, ", ".join(names)))
FieldError: Cannot resolve keyword 'result' into field. Choices are: courseid, courseid_id, createtime, id, name, order, score, scorepeople, teacher, teacher_id, teacher_note, video, videotime, watchpeople, watchrecord, zimu

2017-01-09 12:27:26,135 ERROR 17110 123145310715904 views.py-getvideo:161 Traceback (most recent call last):
  File "/Users/sky-du/workspace/vfastonline/vfast/vcourse/views.py", line 157, in getvideo
    videos = get_results(Video)
  File "/Users/sky-du/workspace/vfastonline/vfast/vfast/api.py", line 123, in get_results
    results = model.objects.filter().values('id', 'result')
  File "/Library/Python/2.7/site-packages/django/db/models/query.py", line 717, in values
    clone = self._values(*fields)
  File "/Library/Python/2.7/site-packages/django/db/models/query.py", line 712, in _values
    query.add_fields(field_names, True)
  File "/Library/Python/2.7/site-packages/django/db/models/sql/query.py", line 1644, in add_fields
    "Choices are: %s" % (name, ", ".join(names)))
FieldError: Cannot resolve keyword 'result' into field. Choices are: courseid, courseid_id, createtime, id, name, order, score, scorepeople, teacher, teacher_id, teacher_note, video, videotime, watchpeople, watchrecord, zimu

2017-01-09 12:28:05,323 ERROR 17110 123145310715904 views.py-getvideo:161 Traceback (most recent call last):
  File "/Users/sky-du/workspace/vfastonline/vfast/vcourse/views.py", line 157, in getvideo
    videos = get_results(Video)
  File "/Users/sky-du/workspace/vfastonline/vfast/vfast/api.py", line 123, in get_results
    results = model.objects.filter().values('id', 'name')
  File "/Library/Python/2.7/site-packages/django/db/models/query.py", line 717, in values
    clone = self._values(*fields)
  File "/Library/Python/2.7/site-packages/django/db/models/query.py", line 712, in _values
    query.add_fields(field_names, True)
  File "/Library/Python/2.7/site-packages/django/db/models/sql/query.py", line 1644, in add_fields
    "Choices are: %s" % (name, ", ".join(names)))
FieldError: Cannot resolve keyword 'result' into field. Choices are: courseid, courseid_id, createtime, id, name, order, score, scorepeople, teacher, teacher_id, teacher_note, video, videotime, watchpeople, watchrecord, zimu

2017-01-09 12:44:41,223 ERROR 17300 123145314922496 views.py-getvideo:158 Traceback (most recent call last):
  File "/Users/sky-du/workspace/vfastonline/vfast/vcourse/views.py", line 155, in getvideo
    video = Video.objects.get(id=id)
  File "/Library/Python/2.7/site-packages/django/db/models/manager.py", line 85, in manager_method
    return getattr(self.get_queryset(), name)(*args, **kwargs)
  File "/Library/Python/2.7/site-packages/django/db/models/query.py", line 385, in get
    self.model._meta.object_name
DoesNotExist: Video matching query does not exist.

2017-01-09 12:44:53,861 ERROR 17300 123145310715904 views.py-getvideo:158 Traceback (most recent call last):
  File "/Users/sky-du/workspace/vfastonline/vfast/vcourse/views.py", line 155, in getvideo
    video = Video.objects.get(id=id)
  File "/Library/Python/2.7/site-packages/django/db/models/manager.py", line 85, in manager_method
    return getattr(self.get_queryset(), name)(*args, **kwargs)
  File "/Library/Python/2.7/site-packages/django/db/models/query.py", line 385, in get
    self.model._meta.object_name
DoesNotExist: Video matching query does not exist.

2017-01-10 01:57:18,265 WARNING 19498 123145310715904 base.py-get_response:152 Not Found: /favicon.ico
2017-01-10 01:57:40,847 WARNING 19498 123145319129088 base.py-get_response:152 Not Found: /course/course
2017-01-10 02:18:10,746 ERROR 19779 123145310715904 views.py-getcourseall:209 Traceback (most recent call last):
  File "/Users/sky-du/workspace/vfastonline/vfast/vcourse/views.py", line 197, in getcourseall
    type_func_object = TypeFunc.objects.get(id=type_func) if type_func else None
  File "/Library/Python/2.7/site-packages/django/db/models/manager.py", line 85, in manager_method
    return getattr(self.get_queryset(), name)(*args, **kwargs)
  File "/Library/Python/2.7/site-packages/django/db/models/query.py", line 385, in get
    self.model._meta.object_name
DoesNotExist: TypeFunc matching query does not exist.

2017-01-10 02:37:01,650 WARNING 20005 123145310715904 base.py-get_response:152 Not Found: /favicon.ico
2017-01-10 03:18:49,462 WARNING 19976 123145310715904 base.py-get_response:152 Not Found: /img/meizitu.jpg
2017-01-10 06:33:43,392 ERROR 21853 123145310715904 views.py-record_video:40 Traceback (most recent call last):
  File "/Users/sky-du/workspace/vfastonline/vfast/record/views.py", line 31, in record_video
    video_progress=video_progress, recordtime=t))
  File "/Library/Python/2.7/site-packages/django/db/models/manager.py", line 85, in manager_method
    return getattr(self.get_queryset(), name)(*args, **kwargs)
  File "/Library/Python/2.7/site-packages/django/db/models/query.py", line 486, in update_or_create
    obj = self.get(**lookup)
  File "/Library/Python/2.7/site-packages/django/db/models/query.py", line 389, in get
    (self.model._meta.object_name, num)
MultipleObjectsReturned: get() returned more than one WatchRecord -- it returned 3!

2017-01-10 06:34:35,947 ERROR 21869 123145310715904 views.py-record_video:40 Traceback (most recent call last):
  File "/Users/sky-du/workspace/vfastonline/vfast/record/views.py", line 31, in record_video
    video_progress=video_progress, recordtime=t))
  File "/Library/Python/2.7/site-packages/django/db/models/manager.py", line 85, in manager_method
    return getattr(self.get_queryset(), name)(*args, **kwargs)
  File "/Library/Python/2.7/site-packages/django/db/models/query.py", line 486, in update_or_create
    obj = self.get(**lookup)
  File "/Library/Python/2.7/site-packages/django/db/models/query.py", line 389, in get
    (self.model._meta.object_name, num)
MultipleObjectsReturned: get() returned more than one WatchRecord -- it returned 3!

2017-01-10 06:34:42,970 ERROR 21869 123145310715904 views.py-record_video:40 Traceback (most recent call last):
  File "/Users/sky-du/workspace/vfastonline/vfast/record/views.py", line 31, in record_video
    video_progress=video_progress, recordtime=t))
  File "/Library/Python/2.7/site-packages/django/db/models/manager.py", line 85, in manager_method
    return getattr(self.get_queryset(), name)(*args, **kwargs)
  File "/Library/Python/2.7/site-packages/django/db/models/query.py", line 486, in update_or_create
    obj = self.get(**lookup)
  File "/Library/Python/2.7/site-packages/django/db/models/query.py", line 389, in get
    (self.model._meta.object_name, num)
MultipleObjectsReturned: get() returned more than one WatchRecord -- it returned 3!

2017-01-10 06:55:29,079 ERROR 22079 123145310715904 views.py-record_score:69 Traceback (most recent call last):
  File "/Users/sky-du/workspace/vfastonline/vfast/record/views.py", line 57, in record_score
    user = User.objects.get(id=uid)
  File "/Library/Python/2.7/site-packages/django/db/models/manager.py", line 85, in manager_method
    return getattr(self.get_queryset(), name)(*args, **kwargs)
  File "/Library/Python/2.7/site-packages/django/db/models/query.py", line 385, in get
    self.model._meta.object_name
DoesNotExist: User matching query does not exist.

2017-01-10 07:44:04,085 ERROR 22615 123145310715904 exception.py-handle_uncaught_exception:124 Internal Server Error: /
Traceback (most recent call last):
  File "/Library/Python/2.7/site-packages/django/core/handlers/exception.py", line 39, in inner
    response = get_response(request)
  File "/Library/Python/2.7/site-packages/django/core/handlers/base.py", line 187, in _get_response
    response = self.process_exception_by_middleware(e, request)
  File "/Library/Python/2.7/site-packages/django/core/handlers/base.py", line 185, in _get_response
    response = wrapped_callback(request, *callback_args, **callback_kwargs)
  File "/Users/sky-du/workspace/vfastonline/vfast/vfast/views.py", line 9, in test
    print get_score_or_watchtime(Score)
  File "/Library/Python/2.7/site-packages/django/db/models/query.py", line 232, in __repr__
    data = list(self[:REPR_OUTPUT_SIZE + 1])
  File "/Library/Python/2.7/site-packages/django/db/models/query.py", line 256, in __iter__
    self._fetch_all()
  File "/Library/Python/2.7/site-packages/django/db/models/query.py", line 1085, in _fetch_all
    self._result_cache = list(self.iterator())
  File "/Library/Python/2.7/site-packages/django/db/models/query.py", line 109, in __iter__
    for row in compiler.results_iter():
  File "/Library/Python/2.7/site-packages/django/db/models/sql/compiler.py", line 789, in results_iter
    results = self.execute_sql(MULTI)
  File "/Library/Python/2.7/site-packages/django/db/models/sql/compiler.py", line 824, in execute_sql
    sql, params = self.as_sql()
  File "/Library/Python/2.7/site-packages/django/db/models/sql/compiler.py", line 369, in as_sql
    extra_select, order_by, group_by = self.pre_sql_setup()
  File "/Library/Python/2.7/site-packages/django/db/models/sql/compiler.py", line 47, in pre_sql_setup
    order_by = self.get_order_by()
  File "/Library/Python/2.7/site-packages/django/db/models/sql/compiler.py", line 293, in get_order_by
    field, self.query.get_meta(), default_order=asc))
  File "/Library/Python/2.7/site-packages/django/db/models/sql/compiler.py", line 553, in find_ordering_name
    field, targets, alias, joins, path, opts = self._setup_joins(pieces, opts, alias)
  File "/Library/Python/2.7/site-packages/django/db/models/sql/compiler.py", line 586, in _setup_joins
    pieces, opts, alias)
  File "/Library/Python/2.7/site-packages/django/db/models/sql/query.py", line 1402, in setup_joins
    names, opts, allow_many, fail_on_missing=True)
  File "/Library/Python/2.7/site-packages/django/db/models/sql/query.py", line 1327, in names_to_path
    "Choices are: %s" % (name, ", ".join(available)))
FieldError: Cannot resolve keyword 'sum' into field. Choices are: courseid, courseid_id, createtime, id, score, sumscore, userid, userid_id
2017-01-10 07:45:08,405 ERROR 22635 123145310715904 exception.py-handle_uncaught_exception:124 Internal Server Error: /
Traceback (most recent call last):
  File "/Library/Python/2.7/site-packages/django/core/handlers/exception.py", line 39, in inner
    response = get_response(request)
  File "/Library/Python/2.7/site-packages/django/core/handlers/base.py", line 187, in _get_response
    response = self.process_exception_by_middleware(e, request)
  File "/Library/Python/2.7/site-packages/django/core/handlers/base.py", line 185, in _get_response
    response = wrapped_callback(request, *callback_args, **callback_kwargs)
  File "/Users/sky-du/workspace/vfastonline/vfast/vfast/views.py", line 10, in test
    print get_score_or_watchtime(WatchRecord, uid=1)
  File "/Users/sky-du/workspace/vfastonline/vfast/record/recordapi.py", line 11, in get_score_or_watchtime
    result = model.objects.values('userid_id').annotate(sumscore=Sum('score')).all().filter(userid=user)
  File "/Library/Python/2.7/site-packages/django/db/models/query.py", line 912, in annotate
    clone.query.add_annotation(annotation, alias, is_summary=False)
  File "/Library/Python/2.7/site-packages/django/db/models/sql/query.py", line 971, in add_annotation
    summarize=is_summary)
  File "/Library/Python/2.7/site-packages/django/db/models/aggregates.py", line 19, in resolve_expression
    c = super(Aggregate, self).resolve_expression(query, allow_joins, reuse, summarize)
  File "/Library/Python/2.7/site-packages/django/db/models/expressions.py", line 513, in resolve_expression
    c.source_expressions[pos] = arg.resolve_expression(query, allow_joins, reuse, summarize, for_save)
  File "/Library/Python/2.7/site-packages/django/db/models/expressions.py", line 463, in resolve_expression
    return query.resolve_ref(self.name, allow_joins, reuse, summarize)
  File "/Library/Python/2.7/site-packages/django/db/models/sql/query.py", line 1462, in resolve_ref
    self.get_initial_alias(), reuse)
  File "/Library/Python/2.7/site-packages/django/db/models/sql/query.py", line 1402, in setup_joins
    names, opts, allow_many, fail_on_missing=True)
  File "/Library/Python/2.7/site-packages/django/db/models/sql/query.py", line 1327, in names_to_path
    "Choices are: %s" % (name, ", ".join(available)))
FieldError: Cannot resolve keyword 'score' into field. Choices are: courseid, courseid_id, id, recordtime, status, userid, userid_id, video_progress, videoid, videoid_id
2017-01-10 08:06:29,420 ERROR 22734 123145310715904 views.py-record_video:44 Traceback (most recent call last):
  File "/Users/sky-du/workspace/vfastonline/vfast/record/views.py", line 26, in record_video
    user = User.objects.get(id=uid)
  File "/Library/Python/2.7/site-packages/django/db/models/manager.py", line 85, in manager_method
    return getattr(self.get_queryset(), name)(*args, **kwargs)
  File "/Library/Python/2.7/site-packages/django/db/models/query.py", line 385, in get
    self.model._meta.object_name
DoesNotExist: User matching query does not exist.

2017-01-10 08:27:10,867 ERROR 23012 123145310715904 views.py-record_video:52 Traceback (most recent call last):
  File "/Users/sky-du/workspace/vfastonline/vfast/record/views.py", line 46, in record_video
    recordtime=t))
TypeError: update() takes exactly 1 argument (2 given)

2017-01-10 09:40:11,569 ERROR 23639 123145314922496 views.py-course_add:51 Traceback (most recent call last):
  File "/Users/sky-du/workspace/vfastonline/vfast/vcourse/views.py", line 37, in course_add
    typefunc = TypeFunc.objects.get(id=type_func).id
  File "/Library/Python/2.7/site-packages/django/db/models/manager.py", line 85, in manager_method
    return getattr(self.get_queryset(), name)(*args, **kwargs)
  File "/Library/Python/2.7/site-packages/django/db/models/query.py", line 376, in get
    clone = self.filter(*args, **kwargs)
  File "/Library/Python/2.7/site-packages/django/db/models/query.py", line 794, in filter
    return self._filter_or_exclude(False, *args, **kwargs)
  File "/Library/Python/2.7/site-packages/django/db/models/query.py", line 812, in _filter_or_exclude
    clone.query.add_q(Q(*args, **kwargs))
  File "/Library/Python/2.7/site-packages/django/db/models/sql/query.py", line 1227, in add_q
    clause, _ = self._add_q(q_object, self.used_aliases)
  File "/Library/Python/2.7/site-packages/django/db/models/sql/query.py", line 1253, in _add_q
    allow_joins=allow_joins, split_subq=split_subq,
  File "/Library/Python/2.7/site-packages/django/db/models/sql/query.py", line 1187, in build_filter
    condition = self.build_lookup(lookups, col, value)
  File "/Library/Python/2.7/site-packages/django/db/models/sql/query.py", line 1083, in build_lookup
    return final_lookup(lhs, rhs)
  File "/Library/Python/2.7/site-packages/django/db/models/lookups.py", line 19, in __init__
    self.rhs = self.get_prep_lookup()
  File "/Library/Python/2.7/site-packages/django/db/models/lookups.py", line 59, in get_prep_lookup
    return self.lhs.output_field.get_prep_value(self.rhs)
  File "/Library/Python/2.7/site-packages/django/db/models/fields/__init__.py", line 946, in get_prep_value
    return int(value)
ValueError: invalid literal for int() with base 10: ''

2017-01-10 09:42:35,696 ERROR 23639 123145310715904 views.py-video_add:100 Traceback (most recent call last):
  File "/Users/sky-du/workspace/vfastonline/vfast/vcourse/views.py", line 69, in video_add
    teacher = User.objects.get(id=teacherid)
  File "/Library/Python/2.7/site-packages/django/db/models/manager.py", line 85, in manager_method
    return getattr(self.get_queryset(), name)(*args, **kwargs)
  File "/Library/Python/2.7/site-packages/django/db/models/query.py", line 376, in get
    clone = self.filter(*args, **kwargs)
  File "/Library/Python/2.7/site-packages/django/db/models/query.py", line 794, in filter
    return self._filter_or_exclude(False, *args, **kwargs)
  File "/Library/Python/2.7/site-packages/django/db/models/query.py", line 812, in _filter_or_exclude
    clone.query.add_q(Q(*args, **kwargs))
  File "/Library/Python/2.7/site-packages/django/db/models/sql/query.py", line 1227, in add_q
    clause, _ = self._add_q(q_object, self.used_aliases)
  File "/Library/Python/2.7/site-packages/django/db/models/sql/query.py", line 1253, in _add_q
    allow_joins=allow_joins, split_subq=split_subq,
  File "/Library/Python/2.7/site-packages/django/db/models/sql/query.py", line 1187, in build_filter
    condition = self.build_lookup(lookups, col, value)
  File "/Library/Python/2.7/site-packages/django/db/models/sql/query.py", line 1083, in build_lookup
    return final_lookup(lhs, rhs)
  File "/Library/Python/2.7/site-packages/django/db/models/lookups.py", line 19, in __init__
    self.rhs = self.get_prep_lookup()
  File "/Library/Python/2.7/site-packages/django/db/models/lookups.py", line 59, in get_prep_lookup
    return self.lhs.output_field.get_prep_value(self.rhs)
  File "/Library/Python/2.7/site-packages/django/db/models/fields/__init__.py", line 946, in get_prep_value
    return int(value)
ValueError: invalid literal for int() with base 10: ''

2017-01-10 09:43:36,548 ERROR 23639 123145310715904 views.py-video_add:100 Traceback (most recent call last):
  File "/Users/sky-du/workspace/vfastonline/vfast/vcourse/views.py", line 97, in video_add
    courseid=course, teacher=teacher, createtime=createtime)
  File "/Library/Python/2.7/site-packages/django/db/models/manager.py", line 85, in manager_method
    return getattr(self.get_queryset(), name)(*args, **kwargs)
  File "/Library/Python/2.7/site-packages/django/db/models/query.py", line 399, in create
    obj.save(force_insert=True, using=self.db)
  File "/Library/Python/2.7/site-packages/django/db/models/base.py", line 796, in save
    force_update=force_update, update_fields=update_fields)
  File "/Library/Python/2.7/site-packages/django/db/models/base.py", line 824, in save_base
    updated = self._save_table(raw, cls, force_insert, force_update, using, update_fields)
  File "/Library/Python/2.7/site-packages/django/db/models/base.py", line 908, in _save_table
    result = self._do_insert(cls._base_manager, using, fields, update_pk, raw)
  File "/Library/Python/2.7/site-packages/django/db/models/base.py", line 947, in _do_insert
    using=using, raw=raw)
  File "/Library/Python/2.7/site-packages/django/db/models/manager.py", line 85, in manager_method
    return getattr(self.get_queryset(), name)(*args, **kwargs)
  File "/Library/Python/2.7/site-packages/django/db/models/query.py", line 1043, in _insert
    return query.get_compiler(using=using).execute_sql(return_id)
  File "/Library/Python/2.7/site-packages/django/db/models/sql/compiler.py", line 1054, in execute_sql
    cursor.execute(sql, params)
  File "/Library/Python/2.7/site-packages/django/db/backends/utils.py", line 79, in execute
    return super(CursorDebugWrapper, self).execute(sql, params)
  File "/Library/Python/2.7/site-packages/django/db/backends/utils.py", line 64, in execute
    return self.cursor.execute(sql, params)
  File "/Library/Python/2.7/site-packages/django/db/utils.py", line 94, in __exit__
    six.reraise(dj_exc_type, dj_exc_value, traceback)
  File "/Library/Python/2.7/site-packages/django/db/backends/utils.py", line 64, in execute
    return self.cursor.execute(sql, params)
  File "/Library/Python/2.7/site-packages/django/db/backends/sqlite3/base.py", line 337, in execute
    return Database.Cursor.execute(self, query, params)
IntegrityError: UNIQUE constraint failed: vcourse_video.order

2017-01-10 09:46:46,844 ERROR 23639 123145310715904 views.py-video_add:100 Traceback (most recent call last):
  File "/Users/sky-du/workspace/vfastonline/vfast/vcourse/views.py", line 97, in video_add
    courseid=course, teacher=teacher, createtime=createtime)
  File "/Library/Python/2.7/site-packages/django/db/models/manager.py", line 85, in manager_method
    return getattr(self.get_queryset(), name)(*args, **kwargs)
  File "/Library/Python/2.7/site-packages/django/db/models/query.py", line 399, in create
    obj.save(force_insert=True, using=self.db)
  File "/Library/Python/2.7/site-packages/django/db/models/base.py", line 796, in save
    force_update=force_update, update_fields=update_fields)
  File "/Library/Python/2.7/site-packages/django/db/models/base.py", line 824, in save_base
    updated = self._save_table(raw, cls, force_insert, force_update, using, update_fields)
  File "/Library/Python/2.7/site-packages/django/db/models/base.py", line 908, in _save_table
    result = self._do_insert(cls._base_manager, using, fields, update_pk, raw)
  File "/Library/Python/2.7/site-packages/django/db/models/base.py", line 947, in _do_insert
    using=using, raw=raw)
  File "/Library/Python/2.7/site-packages/django/db/models/manager.py", line 85, in manager_method
    return getattr(self.get_queryset(), name)(*args, **kwargs)
  File "/Library/Python/2.7/site-packages/django/db/models/query.py", line 1043, in _insert
    return query.get_compiler(using=using).execute_sql(return_id)
  File "/Library/Python/2.7/site-packages/django/db/models/sql/compiler.py", line 1054, in execute_sql
    cursor.execute(sql, params)
  File "/Library/Python/2.7/site-packages/django/db/backends/utils.py", line 79, in execute
    return super(CursorDebugWrapper, self).execute(sql, params)
  File "/Library/Python/2.7/site-packages/django/db/backends/utils.py", line 64, in execute
    return self.cursor.execute(sql, params)
  File "/Library/Python/2.7/site-packages/django/db/utils.py", line 94, in __exit__
    six.reraise(dj_exc_type, dj_exc_value, traceback)
  File "/Library/Python/2.7/site-packages/django/db/backends/utils.py", line 64, in execute
    return self.cursor.execute(sql, params)
  File "/Library/Python/2.7/site-packages/django/db/backends/sqlite3/base.py", line 337, in execute
    return Database.Cursor.execute(self, query, params)
IntegrityError: UNIQUE constraint failed: vcourse_video.order

2017-01-10 10:18:07,503 ERROR 24155 123145310715904 exception.py-handle_uncaught_exception:124 Internal Server Error: /
Traceback (most recent call last):
  File "/Library/Python/2.7/site-packages/django/core/handlers/exception.py", line 39, in inner
    response = get_response(request)
  File "/Library/Python/2.7/site-packages/django/core/handlers/base.py", line 187, in _get_response
    response = self.process_exception_by_middleware(e, request)
  File "/Library/Python/2.7/site-packages/django/core/handlers/base.py", line 185, in _get_response
    response = wrapped_callback(request, *callback_args, **callback_kwargs)
  File "/Users/sky-du/workspace/vfastonline/vfast/vfast/views.py", line 20, in test
    Dumin.objects.create(name=name, time=t)
  File "/Library/Python/2.7/site-packages/django/db/models/manager.py", line 85, in manager_method
    return getattr(self.get_queryset(), name)(*args, **kwargs)
  File "/Library/Python/2.7/site-packages/django/db/models/query.py", line 399, in create
    obj.save(force_insert=True, using=self.db)
  File "/Library/Python/2.7/site-packages/django/db/models/base.py", line 796, in save
    force_update=force_update, update_fields=update_fields)
  File "/Library/Python/2.7/site-packages/django/db/models/base.py", line 824, in save_base
    updated = self._save_table(raw, cls, force_insert, force_update, using, update_fields)
  File "/Library/Python/2.7/site-packages/django/db/models/base.py", line 908, in _save_table
    result = self._do_insert(cls._base_manager, using, fields, update_pk, raw)
  File "/Library/Python/2.7/site-packages/django/db/models/base.py", line 947, in _do_insert
    using=using, raw=raw)
  File "/Library/Python/2.7/site-packages/django/db/models/manager.py", line 85, in manager_method
    return getattr(self.get_queryset(), name)(*args, **kwargs)
  File "/Library/Python/2.7/site-packages/django/db/models/query.py", line 1043, in _insert
    return query.get_compiler(using=using).execute_sql(return_id)
  File "/Library/Python/2.7/site-packages/django/db/models/sql/compiler.py", line 1053, in execute_sql
    for sql, params in self.as_sql():
  File "/Library/Python/2.7/site-packages/django/db/models/sql/compiler.py", line 1006, in as_sql
    for obj in self.query.objs
  File "/Library/Python/2.7/site-packages/django/db/models/sql/compiler.py", line 945, in prepare_value
    value = field.get_db_prep_save(value, connection=self.connection)
  File "/Library/Python/2.7/site-packages/django/db/models/fields/__init__.py", line 755, in get_db_prep_save
    prepared=False)
  File "/Library/Python/2.7/site-packages/django/db/models/fields/__init__.py", line 1438, in get_db_prep_value
    value = self.get_prep_value(value)
  File "/Library/Python/2.7/site-packages/django/db/models/fields/__init__.py", line 1417, in get_prep_value
    value = super(DateTimeField, self).get_prep_value(value)
  File "/Library/Python/2.7/site-packages/django/db/models/fields/__init__.py", line 1275, in get_prep_value
    return self.to_python(value)
  File "/Library/Python/2.7/site-packages/django/db/models/fields/__init__.py", line 1402, in to_python
    params={'value': value},
ValidationError: [u"'2017-01-10 101807' value has an invalid format. It must be in YYYY-MM-DD HH:MM[:ss[.uuuuuu]][TZ] format."]
2017-01-10 10:18:53,255 ERROR 24167 123145310715904 exception.py-handle_uncaught_exception:124 Internal Server Error: /
Traceback (most recent call last):
  File "/Library/Python/2.7/site-packages/django/core/handlers/exception.py", line 39, in inner
    response = get_response(request)
  File "/Library/Python/2.7/site-packages/django/core/handlers/base.py", line 187, in _get_response
    response = self.process_exception_by_middleware(e, request)
  File "/Library/Python/2.7/site-packages/django/core/handlers/base.py", line 185, in _get_response
    response = wrapped_callback(request, *callback_args, **callback_kwargs)
  File "/Users/sky-du/workspace/vfastonline/vfast/vfast/views.py", line 20, in test
    Dumin.objects.create(name=name, time=t)
  File "/Library/Python/2.7/site-packages/django/db/models/manager.py", line 85, in manager_method
    return getattr(self.get_queryset(), name)(*args, **kwargs)
  File "/Library/Python/2.7/site-packages/django/db/models/query.py", line 399, in create
    obj.save(force_insert=True, using=self.db)
  File "/Library/Python/2.7/site-packages/django/db/models/base.py", line 796, in save
    force_update=force_update, update_fields=update_fields)
  File "/Library/Python/2.7/site-packages/django/db/models/base.py", line 824, in save_base
    updated = self._save_table(raw, cls, force_insert, force_update, using, update_fields)
  File "/Library/Python/2.7/site-packages/django/db/models/base.py", line 908, in _save_table
    result = self._do_insert(cls._base_manager, using, fields, update_pk, raw)
  File "/Library/Python/2.7/site-packages/django/db/models/base.py", line 947, in _do_insert
    using=using, raw=raw)
  File "/Library/Python/2.7/site-packages/django/db/models/manager.py", line 85, in manager_method
    return getattr(self.get_queryset(), name)(*args, **kwargs)
  File "/Library/Python/2.7/site-packages/django/db/models/query.py", line 1043, in _insert
    return query.get_compiler(using=using).execute_sql(return_id)
  File "/Library/Python/2.7/site-packages/django/db/models/sql/compiler.py", line 1053, in execute_sql
    for sql, params in self.as_sql():
  File "/Library/Python/2.7/site-packages/django/db/models/sql/compiler.py", line 1006, in as_sql
    for obj in self.query.objs
  File "/Library/Python/2.7/site-packages/django/db/models/sql/compiler.py", line 945, in prepare_value
    value = field.get_db_prep_save(value, connection=self.connection)
  File "/Library/Python/2.7/site-packages/django/db/models/fields/__init__.py", line 755, in get_db_prep_save
    prepared=False)
  File "/Library/Python/2.7/site-packages/django/db/models/fields/__init__.py", line 1438, in get_db_prep_value
    value = self.get_prep_value(value)
  File "/Library/Python/2.7/site-packages/django/db/models/fields/__init__.py", line 1417, in get_prep_value
    value = super(DateTimeField, self).get_prep_value(value)
  File "/Library/Python/2.7/site-packages/django/db/models/fields/__init__.py", line 1275, in get_prep_value
    return self.to_python(value)
  File "/Library/Python/2.7/site-packages/django/db/models/fields/__init__.py", line 1402, in to_python
    params={'value': value},
ValidationError: [u"'2017-01-10 10:M:53' value has an invalid format. It must be in YYYY-MM-DD HH:MM[:ss[.uuuuuu]][TZ] format."]
2017-01-11 02:52:21,964 WARNING 26298 123145310715904 base.py-get_response:152 Not Found: /favicon.ico
2017-01-11 02:54:26,858 ERROR 26322 123145310715904 exception.py-handle_uncaught_exception:124 Internal Server Error: /admin/badge/badge/add/
Traceback (most recent call last):
  File "/Library/Python/2.7/site-packages/django/core/handlers/exception.py", line 39, in inner
    response = get_response(request)
  File "/Library/Python/2.7/site-packages/django/core/handlers/base.py", line 187, in _get_response
    response = self.process_exception_by_middleware(e, request)
  File "/Library/Python/2.7/site-packages/django/core/handlers/base.py", line 185, in _get_response
    response = wrapped_callback(request, *callback_args, **callback_kwargs)
  File "/Library/Python/2.7/site-packages/django/contrib/admin/options.py", line 544, in wrapper
    return self.admin_site.admin_view(view)(*args, **kwargs)
  File "/Library/Python/2.7/site-packages/django/utils/decorators.py", line 149, in _wrapped_view
    response = view_func(request, *args, **kwargs)
  File "/Library/Python/2.7/site-packages/django/views/decorators/cache.py", line 57, in _wrapped_view_func
    response = view_func(request, *args, **kwargs)
  File "/Library/Python/2.7/site-packages/django/contrib/admin/sites.py", line 211, in inner
    return view(request, *args, **kwargs)
  File "/Library/Python/2.7/site-packages/django/contrib/admin/options.py", line 1509, in add_view
    return self.changeform_view(request, None, form_url, extra_context)
  File "/Library/Python/2.7/site-packages/django/utils/decorators.py", line 67, in _wrapper
    return bound_func(*args, **kwargs)
  File "/Library/Python/2.7/site-packages/django/utils/decorators.py", line 149, in _wrapped_view
    response = view_func(request, *args, **kwargs)
  File "/Library/Python/2.7/site-packages/django/utils/decorators.py", line 63, in bound_func
    return func.__get__(self, type(self))(*args2, **kwargs2)
  File "/Library/Python/2.7/site-packages/django/utils/decorators.py", line 185, in inner
    return func(*args, **kwargs)
  File "/Library/Python/2.7/site-packages/django/contrib/admin/options.py", line 1449, in changeform_view
    self.save_model(request, new_object, form, not add)
  File "/Library/Python/2.7/site-packages/django/contrib/admin/options.py", line 1007, in save_model
    obj.save()
  File "/Library/Python/2.7/site-packages/django/db/models/base.py", line 796, in save
    force_update=force_update, update_fields=update_fields)
  File "/Library/Python/2.7/site-packages/django/db/models/base.py", line 824, in save_base
    updated = self._save_table(raw, cls, force_insert, force_update, using, update_fields)
  File "/Library/Python/2.7/site-packages/django/db/models/base.py", line 908, in _save_table
    result = self._do_insert(cls._base_manager, using, fields, update_pk, raw)
  File "/Library/Python/2.7/site-packages/django/db/models/base.py", line 947, in _do_insert
    using=using, raw=raw)
  File "/Library/Python/2.7/site-packages/django/db/models/manager.py", line 85, in manager_method
    return getattr(self.get_queryset(), name)(*args, **kwargs)
  File "/Library/Python/2.7/site-packages/django/db/models/query.py", line 1043, in _insert
    return query.get_compiler(using=using).execute_sql(return_id)
  File "/Library/Python/2.7/site-packages/django/db/models/sql/compiler.py", line 1054, in execute_sql
    cursor.execute(sql, params)
  File "/Library/Python/2.7/site-packages/django/db/backends/utils.py", line 79, in execute
    return super(CursorDebugWrapper, self).execute(sql, params)
  File "/Library/Python/2.7/site-packages/django/db/backends/utils.py", line 64, in execute
    return self.cursor.execute(sql, params)
  File "/Library/Python/2.7/site-packages/django/db/utils.py", line 94, in __exit__
    six.reraise(dj_exc_type, dj_exc_value, traceback)
  File "/Library/Python/2.7/site-packages/django/db/backends/utils.py", line 64, in execute
    return self.cursor.execute(sql, params)
  File "/Library/Python/2.7/site-packages/django/db/backends/sqlite3/base.py", line 337, in execute
    return Database.Cursor.execute(self, query, params)
IntegrityError: NOT NULL constraint failed: badge_badge.cid_id
2017-01-11 06:19:20,911 ERROR 27936 123145310715904 exception.py-handle_uncaught_exception:124 Internal Server Error: /
Traceback (most recent call last):
  File "/Library/Python/2.7/site-packages/django/core/handlers/exception.py", line 39, in inner
    response = get_response(request)
  File "/Library/Python/2.7/site-packages/django/core/handlers/base.py", line 187, in _get_response
    response = self.process_exception_by_middleware(e, request)
  File "/Library/Python/2.7/site-packages/django/core/handlers/base.py", line 185, in _get_response
    response = wrapped_callback(request, *callback_args, **callback_kwargs)
  File "/Users/sky-du/workspace/vfastonline/vfast/vfast/views.py", line 12, in test
    print get_watchtime(WatchRecord)
  File "/Users/sky-du/workspace/vfastonline/vfast/record/recordapi.py", line 23, in get_watchtime
    result = model.objects.values('userid').annotate(sum=Sum('video_progress')).all().order_by('-sum')[0:3]
  File "/Library/Python/2.7/site-packages/django/db/models/manager.py", line 85, in manager_method
    return getattr(self.get_queryset(), name)(*args, **kwargs)
  File "/Library/Python/2.7/site-packages/django/db/models/query.py", line 717, in values
    clone = self._values(*fields)
  File "/Library/Python/2.7/site-packages/django/db/models/query.py", line 712, in _values
    query.add_fields(field_names, True)
  File "/Library/Python/2.7/site-packages/django/db/models/sql/query.py", line 1644, in add_fields
    "Choices are: %s" % (name, ", ".join(names)))
FieldError: Cannot resolve keyword 'userid' into field. Choices are: course, course_id, id, recordtime, status, user, user_id, video, video_id, video_progress
2017-01-11 06:31:57,688 ERROR 28097 123145310715904 exception.py-handle_uncaught_exception:124 Internal Server Error: /
Traceback (most recent call last):
  File "/Library/Python/2.7/site-packages/django/core/handlers/exception.py", line 39, in inner
    response = get_response(request)
  File "/Library/Python/2.7/site-packages/django/core/handlers/base.py", line 187, in _get_response
    response = self.process_exception_by_middleware(e, request)
  File "/Library/Python/2.7/site-packages/django/core/handlers/base.py", line 185, in _get_response
    response = wrapped_callback(request, *callback_args, **callback_kwargs)
  File "/Users/sky-du/workspace/vfastonline/vfast/vfast/views.py", line 8, in test
    print get_score(Score, uid=1)
  File "/Users/sky-du/workspace/vfastonline/vfast/record/recordapi.py", line 10, in get_score
    user = User.objects.get(id=uid)
  File "/Library/Python/2.7/site-packages/django/db/models/manager.py", line 85, in manager_method
    return getattr(self.get_queryset(), name)(*args, **kwargs)
  File "/Library/Python/2.7/site-packages/django/db/models/query.py", line 385, in get
    self.model._meta.object_name
DoesNotExist: User matching query does not exist.
2017-01-11 06:35:56,164 WARNING 28200 123145310715904 base.py-get_response:152 Not Found: /favicon.ico
2017-01-11 06:36:07,026 WARNING 28200 123145310715904 base.py-get_response:152 Not Found: /favicon.ico
2017-01-11 06:40:48,887 WARNING 28200 123145314922496 base.py-get_response:152 Not Found: /course/add
2017-01-11 06:41:49,929 ERROR 28200 123145310715904 views.py-course_add:51 Traceback (most recent call last):
  File "/Users/sky-du/workspace/vfastonline/vfast/vcourse/views.py", line 37, in course_add
    typefunc = TypeFunc.objects.get(id=type_func).id
  File "/Library/Python/2.7/site-packages/django/db/models/manager.py", line 85, in manager_method
    return getattr(self.get_queryset(), name)(*args, **kwargs)
  File "/Library/Python/2.7/site-packages/django/db/models/query.py", line 376, in get
    clone = self.filter(*args, **kwargs)
  File "/Library/Python/2.7/site-packages/django/db/models/query.py", line 794, in filter
    return self._filter_or_exclude(False, *args, **kwargs)
  File "/Library/Python/2.7/site-packages/django/db/models/query.py", line 812, in _filter_or_exclude
    clone.query.add_q(Q(*args, **kwargs))
  File "/Library/Python/2.7/site-packages/django/db/models/sql/query.py", line 1227, in add_q
    clause, _ = self._add_q(q_object, self.used_aliases)
  File "/Library/Python/2.7/site-packages/django/db/models/sql/query.py", line 1253, in _add_q
    allow_joins=allow_joins, split_subq=split_subq,
  File "/Library/Python/2.7/site-packages/django/db/models/sql/query.py", line 1187, in build_filter
    condition = self.build_lookup(lookups, col, value)
  File "/Library/Python/2.7/site-packages/django/db/models/sql/query.py", line 1083, in build_lookup
    return final_lookup(lhs, rhs)
  File "/Library/Python/2.7/site-packages/django/db/models/lookups.py", line 19, in __init__
    self.rhs = self.get_prep_lookup()
  File "/Library/Python/2.7/site-packages/django/db/models/lookups.py", line 59, in get_prep_lookup
    return self.lhs.output_field.get_prep_value(self.rhs)
  File "/Library/Python/2.7/site-packages/django/db/models/fields/__init__.py", line 946, in get_prep_value
    return int(value)
ValueError: invalid literal for int() with base 10: ''

2017-01-11 06:45:36,278 ERROR 28200 123145310715904 views.py-course_add:51 Traceback (most recent call last):
  File "/Users/sky-du/workspace/vfastonline/vfast/vcourse/views.py", line 46, in course_add
    subscibe=subscibe, type_func_id=typefunc, type_lang_id=typelang)
  File "/Library/Python/2.7/site-packages/django/db/models/manager.py", line 85, in manager_method
    return getattr(self.get_queryset(), name)(*args, **kwargs)
  File "/Library/Python/2.7/site-packages/django/db/models/query.py", line 399, in create
    obj.save(force_insert=True, using=self.db)
  File "/Library/Python/2.7/site-packages/django/db/models/base.py", line 796, in save
    force_update=force_update, update_fields=update_fields)
  File "/Library/Python/2.7/site-packages/django/db/models/base.py", line 824, in save_base
    updated = self._save_table(raw, cls, force_insert, force_update, using, update_fields)
  File "/Library/Python/2.7/site-packages/django/db/models/base.py", line 908, in _save_table
    result = self._do_insert(cls._base_manager, using, fields, update_pk, raw)
  File "/Library/Python/2.7/site-packages/django/db/models/base.py", line 947, in _do_insert
    using=using, raw=raw)
  File "/Library/Python/2.7/site-packages/django/db/models/manager.py", line 85, in manager_method
    return getattr(self.get_queryset(), name)(*args, **kwargs)
  File "/Library/Python/2.7/site-packages/django/db/models/query.py", line 1043, in _insert
    return query.get_compiler(using=using).execute_sql(return_id)
  File "/Library/Python/2.7/site-packages/django/db/models/sql/compiler.py", line 1054, in execute_sql
    cursor.execute(sql, params)
  File "/Library/Python/2.7/site-packages/django/db/backends/utils.py", line 79, in execute
    return super(CursorDebugWrapper, self).execute(sql, params)
  File "/Library/Python/2.7/site-packages/django/db/backends/utils.py", line 64, in execute
    return self.cursor.execute(sql, params)
  File "/Library/Python/2.7/site-packages/django/db/utils.py", line 94, in __exit__
    six.reraise(dj_exc_type, dj_exc_value, traceback)
  File "/Library/Python/2.7/site-packages/django/db/backends/utils.py", line 64, in execute
    return self.cursor.execute(sql, params)
  File "/Library/Python/2.7/site-packages/django/db/backends/sqlite3/base.py", line 337, in execute
    return Database.Cursor.execute(self, query, params)
IntegrityError: UNIQUE constraint failed: vcourse_course.order

2017-01-11 06:46:01,809 ERROR 28200 123145310715904 views.py-video_add:100 Traceback (most recent call last):
  File "/Users/sky-du/workspace/vfastonline/vfast/vcourse/views.py", line 69, in video_add
    teacher = User.objects.get(id=teacherid)
  File "/Library/Python/2.7/site-packages/django/db/models/manager.py", line 85, in manager_method
    return getattr(self.get_queryset(), name)(*args, **kwargs)
  File "/Library/Python/2.7/site-packages/django/db/models/query.py", line 376, in get
    clone = self.filter(*args, **kwargs)
  File "/Library/Python/2.7/site-packages/django/db/models/query.py", line 794, in filter
    return self._filter_or_exclude(False, *args, **kwargs)
  File "/Library/Python/2.7/site-packages/django/db/models/query.py", line 812, in _filter_or_exclude
    clone.query.add_q(Q(*args, **kwargs))
  File "/Library/Python/2.7/site-packages/django/db/models/sql/query.py", line 1227, in add_q
    clause, _ = self._add_q(q_object, self.used_aliases)
  File "/Library/Python/2.7/site-packages/django/db/models/sql/query.py", line 1253, in _add_q
    allow_joins=allow_joins, split_subq=split_subq,
  File "/Library/Python/2.7/site-packages/django/db/models/sql/query.py", line 1187, in build_filter
    condition = self.build_lookup(lookups, col, value)
  File "/Library/Python/2.7/site-packages/django/db/models/sql/query.py", line 1083, in build_lookup
    return final_lookup(lhs, rhs)
  File "/Library/Python/2.7/site-packages/django/db/models/lookups.py", line 19, in __init__
    self.rhs = self.get_prep_lookup()
  File "/Library/Python/2.7/site-packages/django/db/models/lookups.py", line 59, in get_prep_lookup
    return self.lhs.output_field.get_prep_value(self.rhs)
  File "/Library/Python/2.7/site-packages/django/db/models/fields/__init__.py", line 946, in get_prep_value
    return int(value)
ValueError: invalid literal for int() with base 10: ''

2017-01-11 06:46:47,518 ERROR 28200 123145310715904 views.py-video_add:100 Traceback (most recent call last):
  File "/Users/sky-du/workspace/vfastonline/vfast/vcourse/views.py", line 69, in video_add
    teacher = User.objects.get(id=teacherid)
  File "/Library/Python/2.7/site-packages/django/db/models/manager.py", line 85, in manager_method
    return getattr(self.get_queryset(), name)(*args, **kwargs)
  File "/Library/Python/2.7/site-packages/django/db/models/query.py", line 376, in get
    clone = self.filter(*args, **kwargs)
  File "/Library/Python/2.7/site-packages/django/db/models/query.py", line 794, in filter
    return self._filter_or_exclude(False, *args, **kwargs)
  File "/Library/Python/2.7/site-packages/django/db/models/query.py", line 812, in _filter_or_exclude
    clone.query.add_q(Q(*args, **kwargs))
  File "/Library/Python/2.7/site-packages/django/db/models/sql/query.py", line 1227, in add_q
    clause, _ = self._add_q(q_object, self.used_aliases)
  File "/Library/Python/2.7/site-packages/django/db/models/sql/query.py", line 1253, in _add_q
    allow_joins=allow_joins, split_subq=split_subq,
  File "/Library/Python/2.7/site-packages/django/db/models/sql/query.py", line 1187, in build_filter
    condition = self.build_lookup(lookups, col, value)
  File "/Library/Python/2.7/site-packages/django/db/models/sql/query.py", line 1083, in build_lookup
    return final_lookup(lhs, rhs)
  File "/Library/Python/2.7/site-packages/django/db/models/lookups.py", line 19, in __init__
    self.rhs = self.get_prep_lookup()
  File "/Library/Python/2.7/site-packages/django/db/models/lookups.py", line 59, in get_prep_lookup
    return self.lhs.output_field.get_prep_value(self.rhs)
  File "/Library/Python/2.7/site-packages/django/db/models/fields/__init__.py", line 946, in get_prep_value
    return int(value)
ValueError: invalid literal for int() with base 10: ''

2017-01-11 06:47:51,805 ERROR 28200 123145310715904 views.py-video_add:100 Traceback (most recent call last):
  File "/Users/sky-du/workspace/vfastonline/vfast/vcourse/views.py", line 97, in video_add
    course=course, teacher=teacher, createtime=createtime)
  File "/Library/Python/2.7/site-packages/django/db/models/manager.py", line 85, in manager_method
    return getattr(self.get_queryset(), name)(*args, **kwargs)
  File "/Library/Python/2.7/site-packages/django/db/models/query.py", line 399, in create
    obj.save(force_insert=True, using=self.db)
  File "/Library/Python/2.7/site-packages/django/db/models/base.py", line 796, in save
    force_update=force_update, update_fields=update_fields)
  File "/Library/Python/2.7/site-packages/django/db/models/base.py", line 824, in save_base
    updated = self._save_table(raw, cls, force_insert, force_update, using, update_fields)
  File "/Library/Python/2.7/site-packages/django/db/models/base.py", line 908, in _save_table
    result = self._do_insert(cls._base_manager, using, fields, update_pk, raw)
  File "/Library/Python/2.7/site-packages/django/db/models/base.py", line 947, in _do_insert
    using=using, raw=raw)
  File "/Library/Python/2.7/site-packages/django/db/models/manager.py", line 85, in manager_method
    return getattr(self.get_queryset(), name)(*args, **kwargs)
  File "/Library/Python/2.7/site-packages/django/db/models/query.py", line 1043, in _insert
    return query.get_compiler(using=using).execute_sql(return_id)
  File "/Library/Python/2.7/site-packages/django/db/models/sql/compiler.py", line 1054, in execute_sql
    cursor.execute(sql, params)
  File "/Library/Python/2.7/site-packages/django/db/backends/utils.py", line 79, in execute
    return super(CursorDebugWrapper, self).execute(sql, params)
  File "/Library/Python/2.7/site-packages/django/db/backends/utils.py", line 64, in execute
    return self.cursor.execute(sql, params)
  File "/Library/Python/2.7/site-packages/django/db/utils.py", line 94, in __exit__
    six.reraise(dj_exc_type, dj_exc_value, traceback)
  File "/Library/Python/2.7/site-packages/django/db/backends/utils.py", line 64, in execute
    return self.cursor.execute(sql, params)
  File "/Library/Python/2.7/site-packages/django/db/backends/sqlite3/base.py", line 337, in execute
    return Database.Cursor.execute(self, query, params)
IntegrityError: UNIQUE constraint failed: vcourse_video.order

2017-01-11 06:47:58,841 ERROR 28200 123145310715904 views.py-video_add:100 Traceback (most recent call last):
  File "/Users/sky-du/workspace/vfastonline/vfast/vcourse/views.py", line 97, in video_add
    course=course, teacher=teacher, createtime=createtime)
  File "/Library/Python/2.7/site-packages/django/db/models/manager.py", line 85, in manager_method
    return getattr(self.get_queryset(), name)(*args, **kwargs)
  File "/Library/Python/2.7/site-packages/django/db/models/query.py", line 399, in create
    obj.save(force_insert=True, using=self.db)
  File "/Library/Python/2.7/site-packages/django/db/models/base.py", line 796, in save
    force_update=force_update, update_fields=update_fields)
  File "/Library/Python/2.7/site-packages/django/db/models/base.py", line 824, in save_base
    updated = self._save_table(raw, cls, force_insert, force_update, using, update_fields)
  File "/Library/Python/2.7/site-packages/django/db/models/base.py", line 908, in _save_table
    result = self._do_insert(cls._base_manager, using, fields, update_pk, raw)
  File "/Library/Python/2.7/site-packages/django/db/models/base.py", line 947, in _do_insert
    using=using, raw=raw)
  File "/Library/Python/2.7/site-packages/django/db/models/manager.py", line 85, in manager_method
    return getattr(self.get_queryset(), name)(*args, **kwargs)
  File "/Library/Python/2.7/site-packages/django/db/models/query.py", line 1043, in _insert
    return query.get_compiler(using=using).execute_sql(return_id)
  File "/Library/Python/2.7/site-packages/django/db/models/sql/compiler.py", line 1054, in execute_sql
    cursor.execute(sql, params)
  File "/Library/Python/2.7/site-packages/django/db/backends/utils.py", line 79, in execute
    return super(CursorDebugWrapper, self).execute(sql, params)
  File "/Library/Python/2.7/site-packages/django/db/backends/utils.py", line 64, in execute
    return self.cursor.execute(sql, params)
  File "/Library/Python/2.7/site-packages/django/db/utils.py", line 94, in __exit__
    six.reraise(dj_exc_type, dj_exc_value, traceback)
  File "/Library/Python/2.7/site-packages/django/db/backends/utils.py", line 64, in execute
    return self.cursor.execute(sql, params)
  File "/Library/Python/2.7/site-packages/django/db/backends/sqlite3/base.py", line 337, in execute
    return Database.Cursor.execute(self, query, params)
IntegrityError: UNIQUE constraint failed: vcourse_video.order

2017-01-11 06:48:46,486 ERROR 28200 123145310715904 exception.py-handle_uncaught_exception:124 Internal Server Error: /admin/record/score/add/
Traceback (most recent call last):
  File "/Library/Python/2.7/site-packages/django/core/handlers/exception.py", line 39, in inner
    response = get_response(request)
  File "/Library/Python/2.7/site-packages/django/core/handlers/base.py", line 187, in _get_response
    response = self.process_exception_by_middleware(e, request)
  File "/Library/Python/2.7/site-packages/django/core/handlers/base.py", line 185, in _get_response
    response = wrapped_callback(request, *callback_args, **callback_kwargs)
  File "/Library/Python/2.7/site-packages/django/contrib/admin/options.py", line 544, in wrapper
    return self.admin_site.admin_view(view)(*args, **kwargs)
  File "/Library/Python/2.7/site-packages/django/utils/decorators.py", line 149, in _wrapped_view
    response = view_func(request, *args, **kwargs)
  File "/Library/Python/2.7/site-packages/django/views/decorators/cache.py", line 57, in _wrapped_view_func
    response = view_func(request, *args, **kwargs)
  File "/Library/Python/2.7/site-packages/django/contrib/admin/sites.py", line 211, in inner
    return view(request, *args, **kwargs)
  File "/Library/Python/2.7/site-packages/django/contrib/admin/options.py", line 1509, in add_view
    return self.changeform_view(request, None, form_url, extra_context)
  File "/Library/Python/2.7/site-packages/django/utils/decorators.py", line 67, in _wrapper
    return bound_func(*args, **kwargs)
  File "/Library/Python/2.7/site-packages/django/utils/decorators.py", line 149, in _wrapped_view
    response = view_func(request, *args, **kwargs)
  File "/Library/Python/2.7/site-packages/django/utils/decorators.py", line 63, in bound_func
    return func.__get__(self, type(self))(*args2, **kwargs2)
  File "/Library/Python/2.7/site-packages/django/utils/decorators.py", line 185, in inner
    return func(*args, **kwargs)
  File "/Library/Python/2.7/site-packages/django/contrib/admin/options.py", line 1453, in changeform_view
    self.log_addition(request, new_object, change_message)
  File "/Library/Python/2.7/site-packages/django/contrib/admin/options.py", line 719, in log_addition
    object_repr=force_text(object),
  File "/Library/Python/2.7/site-packages/django/utils/encoding.py", line 78, in force_text
    s = six.text_type(s)
  File "/Users/sky-du/workspace/vfastonline/vfast/record/models.py", line 17, in __unicode__
    return self.userid.username
AttributeError: 'Score' object has no attribute 'userid'
2017-01-11 06:51:26,038 ERROR 28344 123145310715904 exception.py-handle_uncaught_exception:124 Internal Server Error: /admin/record/watchrecord/add/
Traceback (most recent call last):
  File "/Library/Python/2.7/site-packages/django/core/handlers/exception.py", line 39, in inner
    response = get_response(request)
  File "/Library/Python/2.7/site-packages/django/core/handlers/base.py", line 187, in _get_response
    response = self.process_exception_by_middleware(e, request)
  File "/Library/Python/2.7/site-packages/django/core/handlers/base.py", line 185, in _get_response
    response = wrapped_callback(request, *callback_args, **callback_kwargs)
  File "/Library/Python/2.7/site-packages/django/contrib/admin/options.py", line 544, in wrapper
    return self.admin_site.admin_view(view)(*args, **kwargs)
  File "/Library/Python/2.7/site-packages/django/utils/decorators.py", line 149, in _wrapped_view
    response = view_func(request, *args, **kwargs)
  File "/Library/Python/2.7/site-packages/django/views/decorators/cache.py", line 57, in _wrapped_view_func
    response = view_func(request, *args, **kwargs)
  File "/Library/Python/2.7/site-packages/django/contrib/admin/sites.py", line 211, in inner
    return view(request, *args, **kwargs)
  File "/Library/Python/2.7/site-packages/django/contrib/admin/options.py", line 1509, in add_view
    return self.changeform_view(request, None, form_url, extra_context)
  File "/Library/Python/2.7/site-packages/django/utils/decorators.py", line 67, in _wrapper
    return bound_func(*args, **kwargs)
  File "/Library/Python/2.7/site-packages/django/utils/decorators.py", line 149, in _wrapped_view
    response = view_func(request, *args, **kwargs)
  File "/Library/Python/2.7/site-packages/django/utils/decorators.py", line 63, in bound_func
    return func.__get__(self, type(self))(*args2, **kwargs2)
  File "/Library/Python/2.7/site-packages/django/utils/decorators.py", line 185, in inner
    return func(*args, **kwargs)
  File "/Library/Python/2.7/site-packages/django/contrib/admin/options.py", line 1453, in changeform_view
    self.log_addition(request, new_object, change_message)
  File "/Library/Python/2.7/site-packages/django/contrib/admin/options.py", line 719, in log_addition
    object_repr=force_text(object),
  File "/Library/Python/2.7/site-packages/django/utils/encoding.py", line 78, in force_text
    s = six.text_type(s)
  File "/Users/sky-du/workspace/vfastonline/vfast/record/models.py", line 33, in __unicode__
    return self.userid.username
AttributeError: 'WatchRecord' object has no attribute 'userid'
2017-01-11 06:54:44,821 ERROR 28359 123145310715904 views.py-record_video:51 Traceback (most recent call last):
  File "/Users/sky-du/workspace/vfastonline/vfast/record/views.py", line 38, in record_video
    obj.save()
  File "/Library/Python/2.7/site-packages/django/db/models/base.py", line 796, in save
    force_update=force_update, update_fields=update_fields)
  File "/Library/Python/2.7/site-packages/django/db/models/base.py", line 824, in save_base
    updated = self._save_table(raw, cls, force_insert, force_update, using, update_fields)
  File "/Library/Python/2.7/site-packages/django/db/models/base.py", line 889, in _save_table
    forced_update)
  File "/Library/Python/2.7/site-packages/django/db/models/base.py", line 939, in _do_update
    return filtered._update(values) > 0
  File "/Library/Python/2.7/site-packages/django/db/models/query.py", line 652, in _update
    return query.get_compiler(self.db).execute_sql(CURSOR)
  File "/Library/Python/2.7/site-packages/django/db/models/sql/compiler.py", line 1148, in execute_sql
    cursor = super(SQLUpdateCompiler, self).execute_sql(result_type)
  File "/Library/Python/2.7/site-packages/django/db/models/sql/compiler.py", line 824, in execute_sql
    sql, params = self.as_sql()
  File "/Library/Python/2.7/site-packages/django/db/models/sql/compiler.py", line 1112, in as_sql
    val = field.get_db_prep_save(val, connection=self.connection)
  File "/Library/Python/2.7/site-packages/django/db/models/fields/__init__.py", line 755, in get_db_prep_save
    prepared=False)
  File "/Library/Python/2.7/site-packages/django/db/models/fields/__init__.py", line 1438, in get_db_prep_value
    value = self.get_prep_value(value)
  File "/Library/Python/2.7/site-packages/django/db/models/fields/__init__.py", line 1417, in get_prep_value
    value = super(DateTimeField, self).get_prep_value(value)
  File "/Library/Python/2.7/site-packages/django/db/models/fields/__init__.py", line 1275, in get_prep_value
    return self.to_python(value)
  File "/Library/Python/2.7/site-packages/django/db/models/fields/__init__.py", line 1378, in to_python
    parsed = parse_datetime(value)
  File "/Library/Python/2.7/site-packages/django/utils/dateparse.py", line 93, in parse_datetime
    match = datetime_re.match(value)
TypeError: expected string or buffer

2017-01-11 06:56:07,946 ERROR 28392 123145310715904 views.py-record_video:51 Traceback (most recent call last):
  File "/Users/sky-du/workspace/vfastonline/vfast/record/views.py", line 38, in record_video
    obj.save()
  File "/Library/Python/2.7/site-packages/django/db/models/base.py", line 796, in save
    force_update=force_update, update_fields=update_fields)
  File "/Library/Python/2.7/site-packages/django/db/models/base.py", line 824, in save_base
    updated = self._save_table(raw, cls, force_insert, force_update, using, update_fields)
  File "/Library/Python/2.7/site-packages/django/db/models/base.py", line 889, in _save_table
    forced_update)
  File "/Library/Python/2.7/site-packages/django/db/models/base.py", line 939, in _do_update
    return filtered._update(values) > 0
  File "/Library/Python/2.7/site-packages/django/db/models/query.py", line 652, in _update
    return query.get_compiler(self.db).execute_sql(CURSOR)
  File "/Library/Python/2.7/site-packages/django/db/models/sql/compiler.py", line 1148, in execute_sql
    cursor = super(SQLUpdateCompiler, self).execute_sql(result_type)
  File "/Library/Python/2.7/site-packages/django/db/models/sql/compiler.py", line 824, in execute_sql
    sql, params = self.as_sql()
  File "/Library/Python/2.7/site-packages/django/db/models/sql/compiler.py", line 1112, in as_sql
    val = field.get_db_prep_save(val, connection=self.connection)
  File "/Library/Python/2.7/site-packages/django/db/models/fields/__init__.py", line 755, in get_db_prep_save
    prepared=False)
  File "/Library/Python/2.7/site-packages/django/db/models/fields/__init__.py", line 1438, in get_db_prep_value
    value = self.get_prep_value(value)
  File "/Library/Python/2.7/site-packages/django/db/models/fields/__init__.py", line 1417, in get_prep_value
    value = super(DateTimeField, self).get_prep_value(value)
  File "/Library/Python/2.7/site-packages/django/db/models/fields/__init__.py", line 1275, in get_prep_value
    return self.to_python(value)
  File "/Library/Python/2.7/site-packages/django/db/models/fields/__init__.py", line 1378, in to_python
    parsed = parse_datetime(value)
  File "/Library/Python/2.7/site-packages/django/utils/dateparse.py", line 93, in parse_datetime
    match = datetime_re.match(value)
TypeError: expected string or buffer

2017-01-11 06:59:03,985 ERROR 28428 123145310715904 views.py-record_video:53 Traceback (most recent call last):
  File "/Users/sky-du/workspace/vfastonline/vfast/record/views.py", line 40, in record_video
    recordtime=t)
  File "/Library/Python/2.7/site-packages/django/db/models/query.py", line 635, in update
    rows = query.get_compiler(self.db).execute_sql(CURSOR)
  File "/Library/Python/2.7/site-packages/django/db/models/sql/compiler.py", line 1148, in execute_sql
    cursor = super(SQLUpdateCompiler, self).execute_sql(result_type)
  File "/Library/Python/2.7/site-packages/django/db/models/sql/compiler.py", line 824, in execute_sql
    sql, params = self.as_sql()
  File "/Library/Python/2.7/site-packages/django/db/models/sql/compiler.py", line 1112, in as_sql
    val = field.get_db_prep_save(val, connection=self.connection)
  File "/Library/Python/2.7/site-packages/django/db/models/fields/__init__.py", line 755, in get_db_prep_save
    prepared=False)
  File "/Library/Python/2.7/site-packages/django/db/models/fields/__init__.py", line 1438, in get_db_prep_value
    value = self.get_prep_value(value)
  File "/Library/Python/2.7/site-packages/django/db/models/fields/__init__.py", line 1417, in get_prep_value
    value = super(DateTimeField, self).get_prep_value(value)
  File "/Library/Python/2.7/site-packages/django/db/models/fields/__init__.py", line 1275, in get_prep_value
    return self.to_python(value)
  File "/Library/Python/2.7/site-packages/django/db/models/fields/__init__.py", line 1378, in to_python
    parsed = parse_datetime(value)
  File "/Library/Python/2.7/site-packages/django/utils/dateparse.py", line 93, in parse_datetime
    match = datetime_re.match(value)
TypeError: expected string or buffer

2017-01-11 07:16:15,346 ERROR 28642 123145310715904 exception.py-handle_uncaught_exception:124 Internal Server Error: /
Traceback (most recent call last):
  File "/Library/Python/2.7/site-packages/django/core/handlers/exception.py", line 39, in inner
    response = get_response(request)
  File "/Library/Python/2.7/site-packages/django/core/handlers/base.py", line 187, in _get_response
    response = self.process_exception_by_middleware(e, request)
  File "/Library/Python/2.7/site-packages/django/core/handlers/base.py", line 185, in _get_response
    response = wrapped_callback(request, *callback_args, **callback_kwargs)
  File "/Users/sky-du/workspace/vfastonline/vfast/vfast/views.py", line 12, in test
    get_watched_video(1)
  File "/Users/sky-du/workspace/vfastonline/vfast/record/recordapi.py", line 38, in get_watched_video
    print video.status
AttributeError: 'Video' object has no attribute 'status'
2017-01-11 07:18:29,838 ERROR 28677 123145310715904 exception.py-handle_uncaught_exception:124 Internal Server Error: /
Traceback (most recent call last):
  File "/Library/Python/2.7/site-packages/django/core/handlers/exception.py", line 39, in inner
    response = get_response(request)
  File "/Library/Python/2.7/site-packages/django/core/handlers/base.py", line 187, in _get_response
    response = self.process_exception_by_middleware(e, request)
  File "/Library/Python/2.7/site-packages/django/core/handlers/base.py", line 185, in _get_response
    response = wrapped_callback(request, *callback_args, **callback_kwargs)
  File "/Users/sky-du/workspace/vfastonline/vfast/vfast/views.py", line 12, in test
    get_watched_video(1)
  File "/Users/sky-du/workspace/vfastonline/vfast/record/recordapi.py", line 42, in get_watched_video
    if watch.id == video.id:
AttributeError: 'dict' object has no attribute 'id'
2017-01-11 07:19:42,079 ERROR 28688 123145310715904 exception.py-handle_uncaught_exception:124 Internal Server Error: /
Traceback (most recent call last):
  File "/Library/Python/2.7/site-packages/django/core/handlers/exception.py", line 39, in inner
    response = get_response(request)
  File "/Library/Python/2.7/site-packages/django/core/handlers/base.py", line 187, in _get_response
    response = self.process_exception_by_middleware(e, request)
  File "/Library/Python/2.7/site-packages/django/core/handlers/base.py", line 185, in _get_response
    response = wrapped_callback(request, *callback_args, **callback_kwargs)
  File "/Users/sky-du/workspace/vfastonline/vfast/vfast/views.py", line 12, in test
    get_watched_video(1)
  File "/Users/sky-du/workspace/vfastonline/vfast/record/recordapi.py", line 42, in get_watched_video
    if watch.id == video.id:
AttributeError: 'dict' object has no attribute 'id'
2017-01-11 07:23:55,704 ERROR 28768 123145310715904 exception.py-handle_uncaught_exception:124 Internal Server Error: /
Traceback (most recent call last):
  File "/Library/Python/2.7/site-packages/django/core/handlers/exception.py", line 39, in inner
    response = get_response(request)
  File "/Library/Python/2.7/site-packages/django/core/handlers/base.py", line 187, in _get_response
    response = self.process_exception_by_middleware(e, request)
  File "/Library/Python/2.7/site-packages/django/core/handlers/base.py", line 185, in _get_response
    response = wrapped_callback(request, *callback_args, **callback_kwargs)
  File "/Users/sky-du/workspace/vfastonline/vfast/vfast/views.py", line 12, in test
    get_watched_video(1)
  File "/Users/sky-du/workspace/vfastonline/vfast/record/recordapi.py", line 43, in get_watched_video
    video['status'] == watch['status']
KeyError: 'status'
2017-01-11 07:27:53,864 ERROR 28814 123145310715904 exception.py-handle_uncaught_exception:124 Internal Server Error: /
Traceback (most recent call last):
  File "/Library/Python/2.7/site-packages/django/core/handlers/exception.py", line 39, in inner
    response = get_response(request)
  File "/Library/Python/2.7/site-packages/django/core/handlers/base.py", line 187, in _get_response
    response = self.process_exception_by_middleware(e, request)
  File "/Library/Python/2.7/site-packages/django/core/handlers/base.py", line 185, in _get_response
    response = wrapped_callback(request, *callback_args, **callback_kwargs)
  File "/Users/sky-du/workspace/vfastonline/vfast/vfast/views.py", line 12, in test
    get_watched_video(1)
  File "/Users/sky-du/workspace/vfastonline/vfast/record/recordapi.py", line 43, in get_watched_video
    video.setdefault['status', watch['status']]
TypeError: 'builtin_function_or_method' object has no attribute '__getitem__'
2017-01-11 07:28:30,321 ERROR 28823 123145310715904 exception.py-handle_uncaught_exception:124 Internal Server Error: /
Traceback (most recent call last):
  File "/Library/Python/2.7/site-packages/django/core/handlers/exception.py", line 39, in inner
    response = get_response(request)
  File "/Library/Python/2.7/site-packages/django/core/handlers/base.py", line 187, in _get_response
    response = self.process_exception_by_middleware(e, request)
  File "/Library/Python/2.7/site-packages/django/core/handlers/base.py", line 185, in _get_response
    response = wrapped_callback(request, *callback_args, **callback_kwargs)
  File "/Users/sky-du/workspace/vfastonline/vfast/vfast/views.py", line 12, in test
    get_watched_video(1)
  File "/Users/sky-du/workspace/vfastonline/vfast/record/recordapi.py", line 43, in get_watched_video
    video.setdefault['status', 1]
TypeError: 'builtin_function_or_method' object has no attribute '__getitem__'
2017-01-11 07:37:56,012 ERROR 28949 123145310715904 exception.py-handle_uncaught_exception:124 Internal Server Error: /
Traceback (most recent call last):
  File "/Library/Python/2.7/site-packages/django/core/handlers/exception.py", line 39, in inner
    response = get_response(request)
  File "/Library/Python/2.7/site-packages/django/core/handlers/base.py", line 187, in _get_response
    response = self.process_exception_by_middleware(e, request)
  File "/Library/Python/2.7/site-packages/django/core/handlers/base.py", line 185, in _get_response
    response = wrapped_callback(request, *callback_args, **callback_kwargs)
  File "/Users/sky-du/workspace/vfastonline/vfast/vfast/views.py", line 12, in test
    get_watched_video(1)
  File "/Users/sky-du/workspace/vfastonline/vfast/record/recordapi.py", line 45, in get_watched_video
    video.update({'status':watch['status'], 'video_progress':watch['video_progross']})
KeyError: 'video_progross'
2017-01-13 03:43:11,432 WARNING 40308 123145310715904 base.py-get_response:152 Not Found: /favicon.ico
2017-02-04 09:09:59,353 WARNING 18383 123145310715904 base.py-get_response:152 Not Found: /favicon.ico
2017-02-06 09:14:30,151 WARNING 32046 123145314922496 base.py-get_response:152 Not Found: /favicon.ico
2017-02-06 09:18:01,465 ERROR 32155 123145310715904 views.py-comapny_add:238 Traceback (most recent call last):
  File "/Users/sky-du/workspace/vfastonline/vfast/vuser/views.py", line 203, in comapny_add
    manager = models.User.objects.get(id=manager_id)
  File "/Library/Python/2.7/site-packages/django/db/models/manager.py", line 85, in manager_method
    return getattr(self.get_queryset(), name)(*args, **kwargs)
  File "/Library/Python/2.7/site-packages/django/db/models/query.py", line 385, in get
    self.model._meta.object_name
DoesNotExist: User matching query does not exist.

2017-02-06 09:19:46,151 ERROR 32187 123145310715904 views.py-comapny_add:238 Traceback (most recent call last):
  File "/Users/sky-du/workspace/vfastonline/vfast/vuser/views.py", line 203, in comapny_add
    manager = models.User.objects.get(id=manager_id)
  File "/Library/Python/2.7/site-packages/django/db/models/manager.py", line 85, in manager_method
    return getattr(self.get_queryset(), name)(*args, **kwargs)
  File "/Library/Python/2.7/site-packages/django/db/models/query.py", line 385, in get
    self.model._meta.object_name
DoesNotExist: User matching query does not exist.

2017-02-06 09:22:40,303 ERROR 32187 123145310715904 views.py-comapny_add:219 创建公司时, 保存logo图片, 营业执照错误
2017-02-06 09:22:40,303 ERROR 32187 123145310715904 views.py-comapny_add:219 创建公司时, 保存logo图片, 营业执照错误
2017-02-06 09:22:40,311 ERROR 32187 123145310715904 views.py-comapny_add:238 Traceback (most recent call last):
  File "/Users/sky-du/workspace/vfastonline/vfast/vuser/views.py", line 225, in comapny_add
    send_mail(subject, message, settings.EMAIL_HOST_USER, manager.email)
  File "/Library/Python/2.7/site-packages/django/core/mail/__init__.py", line 58, in send_mail
    mail = EmailMultiAlternatives(subject, message, from_email, recipient_list, connection=connection)
  File "/Library/Python/2.7/site-packages/django/core/mail/message.py", line 483, in __init__
    headers, cc, reply_to,
  File "/Library/Python/2.7/site-packages/django/core/mail/message.py", line 268, in __init__
    raise TypeError('"to" argument must be a list or tuple')
TypeError: "to" argument must be a list or tuple

2017-02-06 09:23:29,773 ERROR 32233 123145310715904 views.py-comapny_add:219 创建公司时, 保存logo图片, 营业执照错误
2017-02-06 09:23:29,774 ERROR 32233 123145310715904 views.py-comapny_add:219 创建公司时, 保存logo图片, 营业执照错误
2017-02-06 09:23:32,350 ERROR 32233 123145310715904 views.py-comapny_add:238 Traceback (most recent call last):
  File "/Users/sky-du/workspace/vfastonline/vfast/vuser/views.py", line 225, in comapny_add
    send_mail(subject, message, settings.EMAIL_HOST_USER, [manager.email,])
  File "/Library/Python/2.7/site-packages/django/core/mail/__init__.py", line 62, in send_mail
    return mail.send()
  File "/Library/Python/2.7/site-packages/django/core/mail/message.py", line 342, in send
    return self.get_connection(fail_silently).send_messages([self])
  File "/Library/Python/2.7/site-packages/django/core/mail/backends/smtp.py", line 107, in send_messages
    sent = self._send(message)
  File "/Library/Python/2.7/site-packages/django/core/mail/backends/smtp.py", line 123, in _send
    self.connection.sendmail(from_email, recipients, message.as_bytes(linesep='\r\n'))
  File "/System/Library/Frameworks/Python.framework/Versions/2.7/lib/python2.7/smtplib.py", line 742, in sendmail
    raise SMTPRecipientsRefused(senderrs)
SMTPRecipientsRefused: {u'1': (550, 'Invalid User: 1')}

2017-02-06 09:26:16,977 ERROR 32233 123145310715904 views.py-comapny_add:219 创建公司时, 保存logo图片, 营业执照错误
2017-02-06 09:26:16,977 ERROR 32233 123145310715904 views.py-comapny_add:219 创建公司时, 保存logo图片, 营业执照错误
2017-02-06 09:26:21,757 ERROR 32233 123145310715904 views.py-comapny_add:238 Traceback (most recent call last):
  File "/Users/sky-du/workspace/vfastonline/vfast/vuser/views.py", line 232, in comapny_add
    audit_status=0, manager_id=manager)
  File "/Library/Python/2.7/site-packages/django/db/models/manager.py", line 85, in manager_method
    return getattr(self.get_queryset(), name)(*args, **kwargs)
  File "/Library/Python/2.7/site-packages/django/db/models/query.py", line 399, in create
    obj.save(force_insert=True, using=self.db)
  File "/Library/Python/2.7/site-packages/django/db/models/base.py", line 796, in save
    force_update=force_update, update_fields=update_fields)
  File "/Library/Python/2.7/site-packages/django/db/models/base.py", line 824, in save_base
    updated = self._save_table(raw, cls, force_insert, force_update, using, update_fields)
  File "/Library/Python/2.7/site-packages/django/db/models/base.py", line 908, in _save_table
    result = self._do_insert(cls._base_manager, using, fields, update_pk, raw)
  File "/Library/Python/2.7/site-packages/django/db/models/base.py", line 947, in _do_insert
    using=using, raw=raw)
  File "/Library/Python/2.7/site-packages/django/db/models/manager.py", line 85, in manager_method
    return getattr(self.get_queryset(), name)(*args, **kwargs)
  File "/Library/Python/2.7/site-packages/django/db/models/query.py", line 1043, in _insert
    return query.get_compiler(using=using).execute_sql(return_id)
  File "/Library/Python/2.7/site-packages/django/db/models/sql/compiler.py", line 1053, in execute_sql
    for sql, params in self.as_sql():
  File "/Library/Python/2.7/site-packages/django/db/models/sql/compiler.py", line 1006, in as_sql
    for obj in self.query.objs
  File "/Library/Python/2.7/site-packages/django/db/models/sql/compiler.py", line 945, in prepare_value
    value = field.get_db_prep_save(value, connection=self.connection)
  File "/Library/Python/2.7/site-packages/django/db/models/fields/related.py", line 909, in get_db_prep_save
    return self.target_field.get_db_prep_save(value, connection=connection)
  File "/Library/Python/2.7/site-packages/django/db/models/fields/__init__.py", line 755, in get_db_prep_save
    prepared=False)
  File "/Library/Python/2.7/site-packages/django/db/models/fields/__init__.py", line 938, in get_db_prep_value
    value = self.get_prep_value(value)
  File "/Library/Python/2.7/site-packages/django/db/models/fields/__init__.py", line 946, in get_prep_value
    return int(value)
TypeError: int() argument must be a string or a number, not 'User'

2017-02-06 09:31:24,401 ERROR 32326 123145310715904 views.py-comapny_add:219 创建公司时, 保存logo图片, 营业执照错误
2017-02-06 09:31:24,401 ERROR 32326 123145310715904 views.py-comapny_add:219 创建公司时, 保存logo图片, 营业执照错误
2017-02-06 09:54:51,889 WARNING 32556 123145310715904 base.py-get_response:152 Not Found: /u/static/js/test.js
2017-02-06 09:54:51,901 WARNING 32556 123145314922496 base.py-get_response:152 Not Found: /u/static/css/test.css
2017-02-06 10:10:58,086 WARNING 32556 123145310715904 base.py-get_response:152 Not Found: /u/static/js/test.js
2017-02-06 10:56:00,321 ERROR 33402 123145310715904 exception.py-handle_uncaught_exception:124 Internal Server Error: /u/compinfo
Traceback (most recent call last):
  File "/Library/Python/2.7/site-packages/django/core/handlers/exception.py", line 39, in inner
    response = get_response(request)
  File "/Library/Python/2.7/site-packages/django/core/handlers/base.py", line 198, in _get_response
    "returned None instead." % (callback.__module__, view_name)
ValueError: The view vuser.views.company_info didn't return an HttpResponse object. It returned None instead.
2017-02-06 10:57:33,492 ERROR 33432 123145310715904 views.py-company_info:268 Traceback (most recent call last):
  File "/Users/sky-du/workspace/vfastonline/vfast/vuser/views.py", line 266, in company_info
    return HttpResponse(json.dumps({'comp':company}, ensure_ascii=False))
  File "/System/Library/Frameworks/Python.framework/Versions/2.7/lib/python2.7/json/__init__.py", line 250, in dumps
    sort_keys=sort_keys, **kw).encode(obj)
  File "/System/Library/Frameworks/Python.framework/Versions/2.7/lib/python2.7/json/encoder.py", line 207, in encode
    chunks = self.iterencode(o, _one_shot=True)
  File "/System/Library/Frameworks/Python.framework/Versions/2.7/lib/python2.7/json/encoder.py", line 270, in iterencode
    return _iterencode(o, 0)
  File "/System/Library/Frameworks/Python.framework/Versions/2.7/lib/python2.7/json/encoder.py", line 184, in default
    raise TypeError(repr(o) + " is not JSON serializable")
TypeError: datetime.datetime(2017, 2, 6, 9, 31, 24, tzinfo=<UTC>) is not JSON serializable

2017-02-06 10:58:53,131 ERROR 33454 123145310715904 views.py-company_info:269 Traceback (most recent call last):
  File "/Users/sky-du/workspace/vfastonline/vfast/vuser/views.py", line 267, in company_info
    return HttpResponse(json.dumps({'comp':company}, ensure_ascii=False))
  File "/System/Library/Frameworks/Python.framework/Versions/2.7/lib/python2.7/json/__init__.py", line 250, in dumps
    sort_keys=sort_keys, **kw).encode(obj)
  File "/System/Library/Frameworks/Python.framework/Versions/2.7/lib/python2.7/json/encoder.py", line 207, in encode
    chunks = self.iterencode(o, _one_shot=True)
  File "/System/Library/Frameworks/Python.framework/Versions/2.7/lib/python2.7/json/encoder.py", line 270, in iterencode
    return _iterencode(o, 0)
  File "/System/Library/Frameworks/Python.framework/Versions/2.7/lib/python2.7/json/encoder.py", line 184, in default
    raise TypeError(repr(o) + " is not JSON serializable")
TypeError: datetime.datetime(2017, 2, 6, 9, 31, 24, tzinfo=<UTC>) is not JSON serializable

2017-02-06 10:59:15,837 ERROR 33461 123145310715904 views.py-company_info:269 Traceback (most recent call last):
  File "/Users/sky-du/workspace/vfastonline/vfast/vuser/views.py", line 267, in company_info
    return HttpResponse(json.dumps({'comp':company}, ensure_ascii=False))
  File "/System/Library/Frameworks/Python.framework/Versions/2.7/lib/python2.7/json/__init__.py", line 250, in dumps
    sort_keys=sort_keys, **kw).encode(obj)
  File "/System/Library/Frameworks/Python.framework/Versions/2.7/lib/python2.7/json/encoder.py", line 207, in encode
    chunks = self.iterencode(o, _one_shot=True)
  File "/System/Library/Frameworks/Python.framework/Versions/2.7/lib/python2.7/json/encoder.py", line 270, in iterencode
    return _iterencode(o, 0)
  File "/System/Library/Frameworks/Python.framework/Versions/2.7/lib/python2.7/json/encoder.py", line 184, in default
    raise TypeError(repr(o) + " is not JSON serializable")
TypeError: datetime.datetime(2017, 2, 6, 9, 31, 24, tzinfo=<UTC>) is not JSON serializable

2017-02-06 10:59:16,914 ERROR 33461 123145314922496 views.py-company_info:269 Traceback (most recent call last):
  File "/Users/sky-du/workspace/vfastonline/vfast/vuser/views.py", line 267, in company_info
    return HttpResponse(json.dumps({'comp':company}, ensure_ascii=False))
  File "/System/Library/Frameworks/Python.framework/Versions/2.7/lib/python2.7/json/__init__.py", line 250, in dumps
    sort_keys=sort_keys, **kw).encode(obj)
  File "/System/Library/Frameworks/Python.framework/Versions/2.7/lib/python2.7/json/encoder.py", line 207, in encode
    chunks = self.iterencode(o, _one_shot=True)
  File "/System/Library/Frameworks/Python.framework/Versions/2.7/lib/python2.7/json/encoder.py", line 270, in iterencode
    return _iterencode(o, 0)
  File "/System/Library/Frameworks/Python.framework/Versions/2.7/lib/python2.7/json/encoder.py", line 184, in default
    raise TypeError(repr(o) + " is not JSON serializable")
TypeError: datetime.datetime(2017, 2, 6, 9, 31, 24, tzinfo=<UTC>) is not JSON serializable

2017-02-06 11:00:50,206 ERROR 33484 123145310715904 views.py-company_info:267 Traceback (most recent call last):
  File "/Users/sky-du/workspace/vfastonline/vfast/vuser/views.py", line 265, in company_info
    return HttpResponse(json.dumps({'comp':company}, ensure_ascii=False))
  File "/System/Library/Frameworks/Python.framework/Versions/2.7/lib/python2.7/json/__init__.py", line 250, in dumps
    sort_keys=sort_keys, **kw).encode(obj)
  File "/System/Library/Frameworks/Python.framework/Versions/2.7/lib/python2.7/json/encoder.py", line 207, in encode
    chunks = self.iterencode(o, _one_shot=True)
  File "/System/Library/Frameworks/Python.framework/Versions/2.7/lib/python2.7/json/encoder.py", line 270, in iterencode
    return _iterencode(o, 0)
  File "/System/Library/Frameworks/Python.framework/Versions/2.7/lib/python2.7/json/encoder.py", line 184, in default
    raise TypeError(repr(o) + " is not JSON serializable")
TypeError: datetime.datetime(2017, 2, 6, 9, 31, 24, tzinfo=<UTC>) is not JSON serializable

2017-02-06 12:50:48,600 ERROR 34701 123145310715904 exception.py-handle_uncaught_exception:124 Internal Server Error: /
Traceback (most recent call last):
  File "/Library/Python/2.7/site-packages/django/core/handlers/exception.py", line 39, in inner
    response = get_response(request)
  File "/Library/Python/2.7/site-packages/django/core/handlers/base.py", line 187, in _get_response
    response = self.process_exception_by_middleware(e, request)
  File "/Library/Python/2.7/site-packages/django/core/handlers/base.py", line 185, in _get_response
    response = wrapped_callback(request, *callback_args, **callback_kwargs)
  File "/Users/sky-du/workspace/vfastonline/vfast/vfast/views.py", line 12, in test
    print get_watchtime(WatchRecord)
  File "/Library/Python/2.7/site-packages/django/db/models/query.py", line 232, in __repr__
    data = list(self[:REPR_OUTPUT_SIZE + 1])
  File "/Library/Python/2.7/site-packages/django/db/models/query.py", line 256, in __iter__
    self._fetch_all()
  File "/Library/Python/2.7/site-packages/django/db/models/query.py", line 1085, in _fetch_all
    self._result_cache = list(self.iterator())
  File "/Library/Python/2.7/site-packages/django/db/models/query.py", line 109, in __iter__
    for row in compiler.results_iter():
  File "/Library/Python/2.7/site-packages/django/db/models/sql/compiler.py", line 789, in results_iter
    results = self.execute_sql(MULTI)
  File "/Library/Python/2.7/site-packages/django/db/models/sql/compiler.py", line 835, in execute_sql
    cursor.execute(sql, params)
  File "/Library/Python/2.7/site-packages/django/db/backends/utils.py", line 79, in execute
    return super(CursorDebugWrapper, self).execute(sql, params)
  File "/Library/Python/2.7/site-packages/django/db/backends/utils.py", line 64, in execute
    return self.cursor.execute(sql, params)
  File "/Library/Python/2.7/site-packages/django/db/utils.py", line 94, in __exit__
    six.reraise(dj_exc_type, dj_exc_value, traceback)
  File "/Library/Python/2.7/site-packages/django/db/backends/utils.py", line 64, in execute
    return self.cursor.execute(sql, params)
  File "/Library/Python/2.7/site-packages/django/db/backends/sqlite3/base.py", line 337, in execute
    return Database.Cursor.execute(self, query, params)
OperationalError: no such table: record_watchrecord
2017-02-06 12:55:19,425 ERROR 34786 123145310715904 views.py-comapny_add:222 创建公司时, 保存logo图片, 营业执照错误
2017-02-06 12:55:19,426 ERROR 34786 123145310715904 views.py-comapny_add:222 创建公司时, 保存logo图片, 营业执照错误
